Workbook

Sheet Foglio1
A1: ID | B1: Età | C1: Sex | D1: Scolarità (anni) | E1: Group | F1: Full_Assessment | G1: Delusion theme | H1: Diagnosi alla dimissione_1 | I1: 1_Diagnosi alla dimissione | J1: 2_Diagnosi alla dimissione | K1: 3_Diagnosi alla dimissione | L1: Diagnosi alla dimissione_2 | M1: Diagnosis Grouping | N1: Motivo del ricovero | O1: Data di ammissione | P1: Data di dimissione | Q1: 1_Diagnosi all'ammissione | R1: 2_Diagnosi all'ammissione | S1: Terapia all'ammissione | T1: Uso di sostanze all'ammissione | U1: Tipo di sostanze all'ammissione | V1: 1_Farmaco durante ricovero | W1: 2_Farmaco durante ricovero | X1: 3_Farmaco durante ricovero | Y1: 4_Farmaco durante ricovero | Z1: 5_Farmaco durante ricovero | AA1: 6_Farmaco durante ricovero | AB1: 7_Farmaco durante ricovero | AC1: 8_Farmaco durante ricovero | AD1: 9_Farmaco durante ricovero | AE1: 10_Farmaco durante ricovero | AF1: 11_Farmaco durante ricovero | AG1: 12_Farmaco durante ricovero | AH1: 1_Terapia alla dimissione | AI1: 1_Terapia alla dimissione (dose) | AJ1: 2_Terapia alla dimissione | AK1: 2_Terapia alla dimissione (dose) | AL1: 3_Terapia alla dimissione | AM1: 3_Terapia alla dimissione (dose) | AN1: 4_Terapia alla dimissione | AO1: 4_Terapia alla dimissione (dose) | AP1: 5_Terapia alla dimissione | AQ1: 5_Terapia alla dimissione (dose) | AR1: 6_Terapia alla dimissione | AS1: 6_Terapia alla dimissione (dose) | AT1: 7_Terapia alla dimissione | AU1: 7_Terapia alla dimissione (dose) | AV1: 8_Terapia alla dimissione | AW1: 8_Terapia alla dimissione (dose) | AX1: Numero di farmaci | AY1: Antipsicotico | AZ1: Stato di TSO al momento del ricovero | BA1: Durata del ricovero (in giorni) | BB1: Numero di ricoveri (entro l'anno) | BC1: Esecuzione di contenzione fisica (Sì/No) | BD1: Presenza e tema del delirio | BE1: Sono note alterazioni a esami di imaging o EEG? | BF1: Se note alterazione a esami di imaging o EEG specificare | BG1: T0_Date | BH1: T0_BABS_1 | BI1: T0_BABS_2 | BJ1: T0_BABS_3 | BK1: T0_BABS_4 | BL1: T0_BABS_5 | BM1: T0_BABS_6 | BN1: T0_BABS_7(NO_SUM) | BO1: T0_BABS_7(NO_SUM) | BP1: T0_CGI_1 | BQ1: T0_CGI_2 | BR1: T0_CGI_3 | BS1: T0_SOFAS | BT1: T0_PANSS_p1 | BU1: T0_PANSS_p2 | BV1: T0_PANSS_p3 | BW1: T0_PANSS_p4 | BX1: T0_PANSS_p5 | BY1: T0_PANSS_p6 | BZ1: T0_PANSS_p7 | CA1: T0_PANSS_n1 | CB1: T0_PANSS_n2 | CC1: T0_PANSS_n3 | CD1: T0_PANSS_n4 | CE1: T0_PANSS_n5 | CF1: T0_PANSS_n6 | CG1: T0_PANSS_n7 | CH1: T0_PANSS_g1 | CI1: T0_PANSS_g2 | CJ1: T0_PANSS_g3 | CK1: T0_PANSS_g4 | CL1: T0_PANSS_g5 | CM1: T0_PANSS_g6 | CN1: T0_PANSS_g7 | CO1: T0_PANSS_g8 | CP1: T0_PANSS_g9 | CQ1: T0_PANSS_g10 | CR1: T0_PANSS_g11 | CS1: T0_PANSS_g12 | CT1: T0_PANSS_g13 | CU1: T0_PANSS_g14 | CV1: T0_PANSS_g15 | CW1: T0_PANSS_g16 | CX1: T0_TOT_PANSS | CY1: T0_POS_PANSS | CZ1: T0_NEG_PANSS | DA1: T0_DIS_PANSS | DB1: T0_EXC_PANSS | DC1: T0_EMO_PANSS | DD1: T0_TALD_CIRCOSTANZIALITà | DE1: T0_TALD_DERAGLIAMENTO | DF1: T0_TALD_TANGENZIALITà | DG1: T0_TALD_DISSOCIAZIONE DEL PENSIERO (INCOERENZA/DISTRAZIONE) | DH1: T0_TALD DIALOGO INTERFERENTE | DI1: T0_TALD_PERSEVERAZIONE | DJ1: T0_TALD_VERBIGERAZIONE | DK1: T0_TALD_INTERRUZIONE DEL PENSIERO | DL1: T0_TALD_ACCELERAZIONE DELL'ELOQUIO | DM1: T0_TALD_LOGORREA | DN1: T0_TALD_ELOQUIO MANIERISTICO | DO1: T0_TALD_PARAFASIA SEMANTICA | DP1: T0_TALD_PARAFASIA FONEMICA | DQ1: T0_TALD_NEOLOGISMI | DR1: T0_TALD_ASSONANZA | DS1: T0_TALD_ECOLALIA | DT1: T0_TALD_POVERTÀ DEL CONTENUTO DELL'ELOQUIO | DU1: T0_TALD_PENSIERO POLARIZZATO | DV1: T0_TALD_PENSIERO RALLENTATO | DW1: T0_TALD_POVERTà DELL'ELOQUIO | DX1: T0_TALD_CONCRETISMO | DY1: T0_TALD_BLOCCO | DZ1: T0_TALD_RUMINAZIONE | EA1: T0_TALD_POVERTà DEL PENSIERO | EB1: T0_TALD_PENSIERO INIBITO | EC1: T0_TALD_DISTURBO RECETTIVO DEL LINGUAGGIO | ED1: T0_TALD_DISTURBO_ESPRESSIVO DEL LINGUAGGIO | EE1: T0_TALD_DISFUNZIONE DELL'INIZIATIVA E DELL'INTENZIONALITà DEL PENSIERO | EF1: T0_TALD_INTERFERENZA DEL PENSIERO | EG1: T0_TALD_PRESSIONE/ACCELERAZIONE DEI PENSIERI | EH1: T0_OBJECTIVE_POSITIVE_TALD | EI1: T0_SUBJECTIVE_NEGATIVE_TALD | EJ1: T0_OBJECTIVE_NEGATIVE_TALD | EK1: T0_SUBJECTIVE_POSITIVE_TALD | EL1: T0_APACS_BRIEF_A_SOVRAINF | EM1: T0_APACS_BRIEF_A_SOTTOINF | EN1: T0_APACS_BRIEF_A_ASSENZA_REFERENTI | EO1: T0_APACS_BRIEF_A_CAMBIO_ARGOM | EP1: T0_APACS_BRIEF_A_INTERVISTA_PROP | EQ1: T0_APACS_BRIEF_A_MS | ER1: T0_APACS_BRIEF_A_DS | ES1: T0_APACS_BRIEF_A_MI | ET1: T0_APACS_BRIEF_A_DI | EU1: T0_APACS_BRIEF_A_Trascr_Fig1_Ironia | EV1: T0_APACS_BRIEF_A_Fig1_Ironia | EW1: T0_APACS_BRIEF_A_Trascr_Fig1_Idioma | EX1: T0_APACS_BRIEF_A_Fig1_Idioma | EY1: T0_APACS_BRIEF_A_BRANO_PROP | EZ1: T0_APACS_BRIEF_A_LING_FIG_1 | FA1: T0_APACS_BRIEF_A_LING_FIG_2 | FB1: T0_APACS_BRIEF_A_LING_FIG_3 | FC1: T0_APACS_BRIEF_A_LING_FIG_1_PROP | FD1: T0_APACS_BRIEF_A_UMORISMO_1 | FE1: T0_APACS_BRIEF_A_UMORISMO_2 | FF1: T0_APACS_BRIEF_A_UMORISMO_PROP | FG1: T0_APACS_BRIEF_A_Trascr_Fig2_ITEM_1 | FH1: T0_APACS_BRIEF_A_Fig2_ITEM_1 | FI1: T0_APACS_BRIEF_A_Trascr_Fig2_ITEM_2 | FJ1: T0_APACS_BRIEF_A_Fig2_ITEM_2 | FK1: T0_APACS_BRIEF_A_Trascr_Fig2_ITEM_3 | FL1: T0_APACS_BRIEF_A_Fig2_ITEM_3 | FM1: T0_APACS_BRIEF_A_Fig2_PROP | FN1: T0_APACS_BRIEF_A_PROD_PROP | FO1: T0_APACS_BRIEF_A_COMP_PROP | FP1: T0_APACS_BRIEF_A_TOTAL | FQ1: T1_Date | FR1: T1_BABS_1 | FS1: T1_BABS_2 | FT1: T1_BABS_3 | FU1: T1_BABS_4 | FV1: T1_BABS_5 | FW1: T1_BABS_6 | FX1: T1_BABS_7(NO_SUM) | FY1: T1_CGI_1 | FZ1: T1_CGI_2 | GA1: T1_CGI_3 | GB1: T1_SOFAS | GC1: T1_PANSS_p1 | GD1: T1_PANSS_p2 | GE1: T1_PANSS_p3 | GF1: T1_PANSS_p4 | GG1: T1_PANSS_p5 | GH1: T1_PANSS_p6 | GI1: T1_PANSS_p7 | GJ1: T1_PANSS_n1 | GK1: T1_PANSS_n2 | GL1: T1_PANSS_n3 | GM1: T1_PANSS_n4 | GN1: T1_PANSS_n5 | GO1: T1_PANSS_n6 | GP1: T1_PANSS_n7 | GQ1: T1_PANSS_g1 | GR1: T1_PANSS_g2 | GS1: T1_PANSS_g3 | GT1: T1_PANSS_g4 | GU1: T1_PANSS_g5 | GV1: T1_PANSS_g6 | GW1: T1_PANSS_g7 | GX1: T1_PANSS_g8 | GY1: T1_PANSS_g9 | GZ1: T1_PANSS_g10 | HA1: T1_PANSS_g11 | HB1: T1_PANSS_g12 | HC1: T1_PANSS_g13 | HD1: T1_PANSS_g14 | HE1: T1_PANSS_g15 | HF1: T1_PANSS_g16 | HG1: T1_TOT_PANSS | HH1: T1_POS_PANSS | HI1: T1_NEG_PANSS | HJ1: T1_DIS_PANSS | HK1: T1_EXC_PANSS | HL1: T1_EMO_PANSS | HM1: T1_TALD_CIRCOSTANZIALITà | HN1: T1_TALD_DERAGLIAMENTO | HO1: T1_TALD_TANGENZIALITà | HP1: T1_TALD_DISSOCIAZIONE DEL PENSIERO (INCOERENZA/DISTRAZIONE) | HQ1: T1_TALD DIALOGO INTERFERENTE | HR1: T1_TALD_PERSEVERAZIONE | HS1: T1_TALD_VERBIGERAZIONE | HT1: T1_TALD_INTERRUZIONE DEL PENSIERO | HU1: T1_TALD_ACCELERAZIONE DELL'ELOQUIO | HV1: T1_TALD_LOGORREA | HW1: T1_TALD_ELOQUIO MANIERISTICO | HX1: T1_TALD_PARAFASIA SEMANTICA | HY1: T1_TALD_PARAFASIA FONEMICA | HZ1: T1_TALD_NEOLOGISMI | IA1: T1_TALD_ASSONANZA | IB1: T1_TALD_ECOLALIA | IC1: T1_TALD_POVERTÀ DEL CONTENUTO DELL'ELOQUIO | ID1: T1_TALD_PENSIERO POLARIZZATO | IE1: T1_TALD_PENSIERO RALLENTATO | IF1: T1_TALD_POVERTà DELL'ELOQUIO | IG1: T1_TALD_CONCRETISMO | IH1: T1_TALD_BLOCCO | II1: T1_TALD_RUMINAZIONE | IJ1: T1_TALD_POVERTà DEL PENSIERO | IK1: T1_TALD_PENSIERO INIBITO | IL1: T1_TALD_DISTURBO RECETTIVO DEL LINGUAGGIO | IM1: T1_TALD_DISTURBO_ESPRESSIVO DEL LINGUAGGIO | IN1: T1_TALD_DISFUNZIONE DELL'INIZIATIVA E DELL'INTENZIONALITà DEL PENSIERO | IO1: T1_TALD_INTERFERENZA DEL PENSIERO | IP1: T1_TALD_PRESSIONE/ACCELERAZIONE DEI PENSIERI | IQ1: T1_OBJECTIVE_POSITIVE_TALD | IR1: T1_SUBJECTIVE_NEGATIVE_TALD | IS1: T1_OBJECTIVE_NEGATIVE_TALD | IT1: T1_SUBJECTIVE_POSITIVE_TALD | IU1: T1_INTERVIEW | IV1: T1_TAT_1 | IW1: T1_TAT_2 | IX1: T1_TAT_3 | IY1: T1_APACS_BRIEF_B_SOVRAINF | IZ1: T1_APACS_BRIEF_B_SOTTOINF | JA1: T1_APACS_BRIEF_B_ASSENZA_REFERENTI | JB1: T1_APACS_BRIEF_B_CAMBIO_ARGOMENTO | JC1: T1_APACS_BRIEF_B_INTERVISTA_PROP | JD1: T1_APACS_BRIEF_B_MS | JE1: T1_APACS_BRIEF_B_DS | JF1: T1_APACS_BRIEF_B_MI | JG1: T1_APACS_BRIEF_B_DI | JH1: T1_APACS_BRIEF_B_Trascr_Fig1_Met | JI1: T1_APACS_BRIEF_B_Fig1_Met | JJ1: T1_APACS_BRIEF_B_Trascr_Fig1_Ironia | JK1: T1_APACS_BRIEF_B_Fig1_Ironia | JL1: T1_APACS_BRIEF_B_BRANO_PROP | JM1: T1_APACS_BRIEF_B_LING_FIG_1 | JN1: T1_APACS_BRIEF_B_LING_FIG_2 | JO1: T1_APACS_BRIEF_B_LING_FIG_3 | JP1: T1_APACS_BRIEF_B_LING_FIG_1_PROP | JQ1: T1_APACS_BRIEF_B_UMORISMO_1 | JR1: T1_APACS_BRIEF_B_UMORISMO_2 | JS1: T1_APACS_BRIEF_B_UMORISMO_PROP | JT1: T1_APACS_BRIEF_B_Trascr_Fig2_ITEM_1 | JU1: T1_APACS_BRIEF_B_Fig2_ITEM_1 | JV1: T1_APACS_BRIEF_B_Trascr_Fig2_ITEM_2 | JW1: T1_APACS_BRIEF_B_Fig2_ITEM_2 | JX1: T1_APACS_BRIEF_B_Trascr_Fig2_ITEM_3 | JY1: T1_APACS_BRIEF_B_Fig2_ITEM_3 | JZ1: T1_APACS_BRIEF_B_Fig2_PROP | KA1: T1_APACS_BRIEF_B_PROD_PROP | KB1: T1_APACS_BRIEF_B_COMP_PROP | KC1: T1_APACS_BRIEF_B_TOTAL | KD1: T1_PMM_01_Trascrizione | KE1: PMM_01_CORR | KF1: PMM_01_INT | KG1: T1_PMM_02_Trascrizione | KH1: PMM_02_CORR | KI1: PMM_02_INT | KJ1: T1_PMM_03_Trascrizione | KK1: PMM_03_CORR | KL1: PMM_03_INT | KM1: T1_PMM_04_Trascrizione | KN1: PMM_04_CORR | KO1: PMM_04_INT | KP1: T1_PMM_05_Trascrizione | KQ1: PMM_05_CORR | KR1: PMM_05_INT | KS1: T1_PMM_06_Trascrizione | KT1: PMM_06_CORR | KU1: PMM_06_INT | KV1: T1_PMM_07_Trascrizione | KW1: PMM_07_CORR | KX1: PMM_07_INT | KY1: T1_PMM_08_Trascrizione | KZ1: PMM_08_CORR | LA1: PMM_08_INT | LB1: T1_PMM_09_Trascrizione | LC1: PMM_09_CORR | LD1: PMM_09_INT | LE1: T1_PMM_10_Trascrizione | LF1: PMM_10_CORR | LG1: PMM_10_INT | LH1: T1_PMM_11_Trascrizione | LI1: PMM_11_CORR | LJ1: PMM_11_INT | LK1: T1_PMM_12_Trascrizione | LL1: PMM_12_CORR | LM1: PMM_12_INT | LN1: T1_PMM_13_Trascrizione | LO1: PMM_13_CORR | LP1: PMM_13_INT | LQ1: T1_PMM_14_Trascrizione | LR1: PMM_14_CORR | LS1: PMM_14_INT | LT1: T1_PMM_CORR_TOT | LU1: T1_PMM_INT_TOT | LV1: WASI_CUBI | LW1: WASI_VOCABOLARIO | LX1: WASI_MATRICI | LY1: WASI_SOMIGLIANZE | LZ1: ABSTRACT_T0 | MA1: ARTIFACT_T0 | MB1: HUMAN_T0 | MC1: NATURAL_T0 | MD1: N_METAPHOR_T0 | ME1: ABSTRACT_T1 | MF1: ARTIFACT_T1 | MG1: HUMAN_T1 | MH1: NATURAL_T1 | MI1: N_METAPHOR_T1
A2: 3fff6cb254bb5874 | B2: 67 | C2: M | D2: 8 | E2: 1 | F2: Yes | G2: Bizarre | H2: 297.1 Disturbo delirante | I2: (296.3) Depressione maggiore, episodio ricorrente | J2: 297.9 Stato paranoide non specificato --Psicosi paranoide | K2: NA | L2: BBB | M2: Schizophrenia and other psychoses | N2: Riacutizzazione psicotica | O2: 45460 | P2: 45479 | Q2: CCC | R2: NA | S2: NA | T2: No | U2: NA | V2: Risperidone | W2: Paroxetina | X2: Zolpidem | Y2: Delorazepam | Z2: Lorazepam | AA2: Flurazepam | AB2: Candesartan/Idroclorotiazide | AC2: Atenololo | AD2: Simvastatina/Ezetimibe | AE2: Metformina | AF2: Empaglifozin/Linagliptin | AG2: Polifenoli | AH2: Risperidone | AI2: 6ml sol h 20 | AJ2: Paroxetina | AK2: 40mg cp h8 | AL2: Fluorazepam | AM2: 30mg cp h 22 | AN2: BBB | AO2: BBB | AP2: BBB | AQ2: BBB | AR2: BBB | AS2: BBB | AT2: BBB | AU2: BBB | AV2: BBB | AW2: BBB | AX2: 4 | AZ2: No | BA2: =(P2-O2) -> 19 | BB2: 0 | BC2: No | BD2: Voci imperative, bestemmie e insulti e pensieri di morte | BG2: 45462 | BH2: 3 | BI2: 1 | BJ2: 3 | BK2: 3 | BL2: 2 | BM2: 1 | BN2: 1 | BO2: =SUM(Foglio1!$BH2:$BM2) -> 13 | BP2: 4 | BQ2: 2 | BR2: 5 | BS2: 61 | BT2: 3 | BU2: 1 | BV2: 4 | BW2: 1 | BX2: 1 | BY2: 1 | BZ2: 1 | CA2: 2 | CB2: 3 | CC2: 3 | CD2: 3 | CE2: 3 | CF2: 2 | CG2: 2 | CH2: 1 | CI2: 3 | CJ2: 4 | CK2: 3 | CL2: 1 | CM2: 2 | CN2: 2 | CO2: 1 | CP2: 3 | CQ2: 1 | CR2: 1 | CS2: 1 | CT2: 1 | CU2: 1 | CV2: 3 | CW2: 3 | CX2: =SUM(Foglio1!$BT2:$CW2) -> 61 | CY2: =SUM(Foglio1!$BT2+Foglio1!$BV2+Foglio1!$CP2+Foglio1!$BY2+Foglio1!$BX2+Foglio1!$CH2+Foglio1!$CS2+Foglio1!$CW2-Foglio1!$CE2) -> 14 | CZ2: =SUM(Foglio1!$CF2+Foglio1!$CA2+Foglio1!$CB2+Foglio1!$CD2+Foglio1!$CN2+Foglio1!$CC2+Foglio1!$CW2+Foglio1!$CO2+Foglio1!$CT2-Foglio1!$BU2) -> 19 | DA2: =SUM(Foglio1!$CG2+Foglio1!$CR2+Foglio1!$CQ2+Foglio1!$BU2+Foglio1!$CE2+Foglio1!$CL2+Foglio1!$CS2+Foglio1!$CT2+Foglio1!$CV2+Foglio1!$CP2) -> 17 | DB2: =SUM(Foglio1!$CU2+Foglio1!$BW2+Foglio1!$BZ2+Foglio1!$CO2+Foglio1!$BX2+Foglio1!$CC2+Foglio1!$CK2+Foglio1!$CW2) -> 14 | DC2: =SUM(Foglio1!$CI2+Foglio1!$CM2+Foglio1!$CJ2+Foglio1!$CK2+Foglio1!$BY2+Foglio1!$CH2+Foglio1!$CV2+Foglio1!$CW2) -> 20 | DD2: 1 | DE2: 0 | DF2: 0 | DG2: 0 | DH2: 0 | DI2: 1 | DJ2: 0 | DK2: 0 | DL2: 0 | DM2: 0 | DN2: 1 | DO2: 0 | DP2: 0 | DQ2: 0 | DR2: 0 | DS2: 0 | DT2: 2 | DU2: 0 | DV2: 2 | DW2: 0 | DX2: 3 | DY2: CCC | DZ2: CCC | EA2: CCC | EB2: CCC | EC2: CCC | ED2: CCC | EE2: CCC | EF2: CCC | EG2: CCC | EH2: =(Foglio1!$DE2+Foglio1!$DH2+Foglio1!$DG2+Foglio1!$DF2+Foglio1!$DM2+Foglio1!$DD2+Foglio1!$DO2+Foglio1!$DL2+Foglio1!$DN2+Foglio1!$DQ2+Foglio1!$DP2+Foglio1!$DT2+Foglio1!$DI2+Foglio1!$DK2+Foglio1!$DU2) -> 5 | EI2: =(Foglio1!$EA2+Foglio1!$EB2+Foglio1!$EE2+Foglio1!$EC2+Foglio1!$ED2+Foglio1!$DZ2+Foglio1!$DY2) -> #VALUE! | EJ2: =(Foglio1!$DW2+Foglio1!$DV2+Foglio1!$DX2) -> 5 | EK2: =(Foglio1!$EG2+Foglio1!$EF2) -> #VALUE! | EL2: 1 | EM2: 0 | EN2: 1 | EO2: 0 | EP2: {=SUM(EL2:EO2/4)} -> 0.5 | EQ2: 1 | ER2: 1 | ES2: 1 | ET2: 1 | EU2: se ci sono i cinghiali hanno paura che li aggrediscono | EV2: 0 | EW2: che sistemano la situazione, i cinghiali li devono fare fuori | EX2: 1 | EY2: =(Foglio1!$EQ2+Foglio1!$ER2+Foglio1!$ES2+Foglio1!$ET2+Foglio1!$EV2+Foglio1!$EX2)/6 -> 0.83333333 | EZ2: 0 | FA2: 0 | FB2: 0 | FC2: =(Foglio1!$EZ2+Foglio1!$FA2+Foglio1!$FB2)/3 -> 0 | FD2: 1 | FE2: 1 | FF2: =(Foglio1!$FD2+Foglio1!$FE2)/2 -> 1 | FG2: Hanno tanti libri che aiutano il sapere | FH2: 0 | FI2: Qualcuno che ruba è cleptomane | FJ2: 0 | FK2: Ci sono da fare le preghiere, il pane serve per mangiare e le preghiere per lo spirito | FL2: 0 | FM2: =(Foglio1!$FH2+Foglio1!$FJ2+Foglio1!$FL2)/3 -> 0 | FN2: =(Foglio1!$EP2) -> 0.5 | FO2: =(Foglio1!$EY2+Foglio1!$FC2+Foglio1!$FF2+Foglio1!$FM2)/4 -> 0.45833333 | FP2: =(Foglio1!$EP2+Foglio1!$EY2+Foglio1!$FC2+Foglio1!$FF2+Foglio1!$FM2)/5 -> 0.46666667 | FQ2: 45475 | FR2: 1 | FS2: 1 | FT2: 0 | FU2: 1 | FV2: 0 | FW2: 0 | FX2: 2 | FY2: 3 | FZ2: 2 | GA2: 6 | GB2: 61 | GC2: 2 | GD2: 0 | GE2: 3 | GF2: 0 | GG2: 0 | GH2: 2 | GI2: 0 | GJ2: 3 | GK2: 2 | GL2: 3 | GM2: 3 | GN2: 2 | GO2: 3 | GP2: 0 | GQ2: 3 | GR2: 2 | GS2: 3 | GT2: 2 | GU2: 0 | GV2: 2 | GW2: 2 | GX2: 0 | GY2: 2 | GZ2: 0 | HA2: 0 | HB2: 0 | HC2: 2 | HD2: 0 | HE2: 3 | HF2: 2 | HG2: =SUM(GC2:HF2) -> 46 | HH2: =SUM(GC2+GE2+GY2+GH2+GG2+GQ2+HB2+HF2-GN2) -> 12 | HI2: =SUM(GO2+GJ2+GK2+GM2+GW2+GL2+HF2+GX2+HC2-GD2) -> 20 | HJ2: =SUM(GP2+HA2+GZ2+GD2+GN2+GU2+HB2+HC2+HE2+GY2) -> 9 | HK2: =SUM(HD2+GF2+GI2+GX2+GG2+GL2+GT2+HF2) -> 7 | HL2: =SUM(GR2+GV2+GS2+GT2+GH2+GQ2+HE2+HF2) -> 19 | HM2: 0 | HN2: 0 | HO2: 0 | HP2: 0 | HQ2: 0 | HR2: 0 | HS2: 0 | HT2: 1 | HU2: 0 | HV2: 0 | HW2: 0 | HX2: 0 | HY2: 0 | HZ2: 0 | IA2: 0 | IB2: 0 | IC2: 0 | ID2: 0 | IE2: 3 | IF2: 0 | IG2: 2 | IH2: CCC | II2: CCC | IJ2: CCC | IK2: CCC | IL2: CCC | IM2: CCC | IN2: CCC | IO2: CCC | IP2: CCC | IQ2: CCC | IR2: CCC | IS2: CCC | IT2: CCC | IU2: AAA | IV2: AAA | IW2: AAA | IX2: AAA | IY2: 1 | IZ2: 0 | JA2: 1 | JB2: 1 | JC2: =(Foglio1!$IY2+Foglio1!$IZ2+Foglio1!$JA2+Foglio1!$JB2)/4 -> 0.75 | JD2: 0 | JE2: 0 | JF2: 0 | JG2: 0 | JH2: è un fiore all'occhiello | JI2: 0 | JJ2: che vengono a lavorare dal comune | JK2: 0 | JL2: =(Foglio1!$JD2+Foglio1!$JE2+Foglio1!$JF2+Foglio1!$JG2+Foglio1!$JI2+Foglio1!$JK2)/6 -> 0 | JM2: 1 | JN2: 0 | JO2: 1 | JP2: =(Foglio1!$JM2+Foglio1!$JN2+Foglio1!$JO2)/3 -> 0.66666667 | JQ2: 0 | JR2: 0 | JS2: =(Foglio1!$JQ2+Foglio1!$JR2)/2 -> 0 | JT2: vogliono approfittare di qualcun altro | JU2: 0 | JV2: è un cane buono | JW2: 0 | JX2: c'è la testa, la croce | JY2: 0 | JZ2: =(Foglio1!$JU2+Foglio1!$JW2+Foglio1!$JY2)/3 -> 0 | KA2: =(Foglio1!$JC2) -> 0.75 | KB2: =(Foglio1!$JL2+Foglio1!$JP2+Foglio1!$JS2+Foglio1!$JZ2)/4 -> 0.16666667 | KC2: =(Foglio1!$JC2+Foglio1!$JL2+Foglio1!$JP2+Foglio1!$JS2+Foglio1!$JZ2)/5 -> 0.28333333 | KD2: vanno da una parte all'altra | KE2: 0 | KF2: 1 | KG2: sono come il grano, sono belle | KH2: 0 | KI2: 1 | KJ2: sono il bastone della vecchiaia | KK2: 1 | KL2: 2 | KP2: ti possono salvare nel momento del bisogno | KQ2: 2 | KR2: 3 | KS2: sono lenti | KT2: 2 | KU2: 1 | KV2: è grosso | KW2: 1 | KX2: 1 | KY2: vanno in giro con la testa | KZ2: 1 | LA2: 2 | LB2: sono bravi a cantare | LC2: 2 | LD2: 1 | LE2: sono i bastoni della vecchiaia | LF2: 0 | LG2: 2 | LH2: stanno sempre al sole | LI2: 2 | LJ2: 1 | LK2: si danno delle arie | LL2: 2 | LM2: 3 | LN2: sono piccoli | LO2: 1 | LP2: 1 | LQ2: hanno il senso del sapere | LR2: 1 | LS2: 2 | LT2: =(Foglio1!$KE2+Foglio1!$KH2+Foglio1!$KK2+Foglio1!$KN2+Foglio1!$KQ2+Foglio1!$KT2+Foglio1!$KW2+Foglio1!$KZ2+Foglio1!$LC2+Foglio1!$LF2+Foglio1!$LI2+Foglio1!$LL2+Foglio1!$LO2+Foglio1!$LR2) -> 15 | LU2: =(Foglio1!$KI2+Foglio1!$KF2+Foglio1!$KL2+Foglio1!$KO2+Foglio1!$KR2+Foglio1!$KU2+Foglio1!$KX2+Foglio1!$LA2+Foglio1!$LD2+Foglio1!$LG2+Foglio1!$LJ2+Foglio1!$LM2+Foglio1!$LP2+Foglio1!$LS2) -> 21 | LV2: 6 | LW2: 27 | LX2: 7 | LY2: 19 | LZ2: 1 | MA2: 2 | MB2: 3 | MC2: 0 | MD2: =SUM(LZ2:MC2) -> 6 | ME2: 0 | MF2: 2 | MG2: 2 | MH2: 0 | MI2: =SUM(ME2:MH2) -> 4
A3: 65ab2c5204d71127 | B3: 58 | C3: F | D3: 8 | E3: 1 | F3: Yes | G3: Persecutory | H3: 297.1 Disturbo delirante | I3: (297.1) Disturbo delirante | J3: BBB | K3: NA | L3: BBB | M3: Schizophrenia and other psychoses | N3: Scompenso psicotico | O3: 45460 | P3: 45475 | Q3: Disturbo delirante | R3: NA | S3: Olanzapina | T3: Sì | U3: Alcool | V3: Olanzapina | W3: Paliperidone | X3: Aloperidolo | Y3: Promazina | Z3: Delorazepam | AA3: Tiamina | AH3: Paliperidone | AI3: 6 mg | AJ3: BBB | AK3: BBB | AL3: BBB | AM3: BBB | AN3: BBB | AO3: BBB | AP3: BBB | AQ3: BBB | AR3: BBB | AS3: BBB | AT3: BBB | AU3: BBB | AV3: BBB | AW3: BBB | AX3: 1 | AZ3: Sì | BA3: =(P3-O3) -> 15 | BB3: 0 | BC3: No | BD3: Vicini di casa le fanno dispetti | BE3: No | BF3: NA | BG3: 45460 | BH3: 3 | BI3: 1 | BJ3: 3 | BK3: 3 | BL3: 2 | BM3: 4 | BN3: 3 | BO3: =SUM(Foglio1!$BH3:$BM3) -> 16 | BP3: 5 | BQ3: 3 | BR3: 9 | BS3: 51 | BT3: 4 | BU3: 3 | BV3: 3 | BW3: 2 | BX3: 1 | BY3: 5 | BZ3: 3 | CA3: 1 | CB3: 1 | CC3: 1 | CD3: 2 | CE3: 3 | CF3: 4 | CG3: 5 | CH3: 2 | CI3: 1 | CJ3: 2 | CK3: 2 | CL3: 4 | CM3: 2 | CN3: 1 | CO3: 3 | CP3: 4 | CQ3: 1 | CR3: 1 | CS3: 3 | CT3: 1 | CU3: 4 | CV3: 3 | CW3: 3 | CX3: =SUM(Foglio1!$BT3:$CW3) -> 75 | CY3: =SUM(Foglio1!$BT3+Foglio1!$BV3+Foglio1!$CP3+Foglio1!$BY3+Foglio1!$BX3+Foglio1!$CH3+Foglio1!$CS3+Foglio1!$CW3-Foglio1!$CE3) -> 22 | CZ3: =SUM(Foglio1!$CF3+Foglio1!$CA3+Foglio1!$CB3+Foglio1!$CD3+Foglio1!$CN3+Foglio1!$CC3+Foglio1!$CW3+Foglio1!$CO3+Foglio1!$CT3-Foglio1!$BU3) -> 14 | DA3: =SUM(Foglio1!$CG3+Foglio1!$CR3+Foglio1!$CQ3+Foglio1!$BU3+Foglio1!$CE3+Foglio1!$CL3+Foglio1!$CS3+Foglio1!$CT3+Foglio1!$CV3+Foglio1!$CP3) -> 28 | DB3: =SUM(Foglio1!$CU3+Foglio1!$BW3+Foglio1!$BZ3+Foglio1!$CO3+Foglio1!$BX3+Foglio1!$CC3+Foglio1!$CK3+Foglio1!$CW3) -> 19 | DC3: =SUM(Foglio1!$CI3+Foglio1!$CM3+Foglio1!$CJ3+Foglio1!$CK3+Foglio1!$BY3+Foglio1!$CH3+Foglio1!$CV3+Foglio1!$CW3) -> 20 | DD3: 0 | DE3: 0 | DF3: 0 | DG3: 0 | DH3: 0 | DI3: 0 | DJ3: 0 | DK3: 0 | DL3: 0 | DM3: 0 | DN3: 0 | DO3: 0 | DP3: 0 | DQ3: 0 | DR3: 0 | DS3: 0 | DT3: 1 | DU3: 0 | DV3: 0 | DW3: 0 | DX3: 2 | DY3: CCC | DZ3: CCC | EA3: CCC | EB3: CCC | EC3: CCC | ED3: CCC | EE3: CCC | EF3: CCC | EG3: CCC | EH3: =(Foglio1!$DE3+Foglio1!$DH3+Foglio1!$DG3+Foglio1!$DF3+Foglio1!$DM3+Foglio1!$DD3+Foglio1!$DO3+Foglio1!$DL3+Foglio1!$DN3+Foglio1!$DQ3+Foglio1!$DP3+Foglio1!$DT3+Foglio1!$DI3+Foglio1!$DK3+Foglio1!$DU3) -> 1 | EI3: =(Foglio1!$EA3+Foglio1!$EB3+Foglio1!$EE3+Foglio1!$EC3+Foglio1!$ED3+Foglio1!$DZ3+Foglio1!$DY3) -> #VALUE! | EJ3: =(Foglio1!$DW3+Foglio1!$DV3+Foglio1!$DX3) -> 2 | EK3: =(Foglio1!$EG3+Foglio1!$EF3) -> #VALUE! | EL3: 1 | EM3: 0 | EN3: 1 | EO3: 1 | EP3: {=SUM(EL3:EO3/4)} -> 0.75 | EQ3: 0 | ER3: 0 | ES3: 1 | ET3: 0 | EU3: i negozi di paese chiusi e poi ci sono i centri commerciali | EV3: 0 | EW3: per grestire cose nuove il sindaco ha fatto cose utili | EX3: 0 | EY3: =(Foglio1!$EQ3+Foglio1!$ER3+Foglio1!$ES3+Foglio1!$ET3+Foglio1!$EV3+Foglio1!$EX3)/6 -> 0.16666667 | EZ3: 1 | FA3: 1 | FB3: 1 | FC3: =(Foglio1!$EZ3+Foglio1!$FA3+Foglio1!$FB3)/3 -> 1 | FD3: 0 | FE3: 1 | FF3: =(Foglio1!$FD3+Foglio1!$FE3)/2 -> 0.5 | FG3: si può allargare l'immaginazione anche leggendo un libro | FH3: 0 | FI3: l'adulterio, se lasci una cosa gli altri te la possono prendere | FJ3: 0 | FK3: non sa rispondere | FL3: 0 | FM3: =(Foglio1!$FH3+Foglio1!$FJ3+Foglio1!$FL3)/3 -> 0 | FN3: =(Foglio1!$EP3) -> 0.75 | FO3: =(Foglio1!$EY3+Foglio1!$FC3+Foglio1!$FF3+Foglio1!$FM3)/4 -> 0.41666667 | FP3: =(Foglio1!$EP3+Foglio1!$EY3+Foglio1!$FC3+Foglio1!$FF3+Foglio1!$FM3)/5 -> 0.48333333 | FQ3: 45474 | FR3: 2 | FS3: 2 | FT3: 1 | FU3: 2 | FV3: 1 | FW3: 3 | FX3: 3 | FY3: 3 | FZ3: 2 | GA3: 6 | GB3: 61 | GC3: 2 | GD3: 0 | GE3: 0 | GF3: 1 | GG3: 0 | GH3: 3 | GI3: 2 | GJ3: 2 | GK3: 0 | GL3: 2 | GM3: 3 | GN3: 3 | GO3: 0 | GP3: 0 | GQ3: 0 | GR3: 2 | GS3: 2 | GT3: 3 | GU3: 0 | GV3: 2 | GW3: 0 | GX3: 0 | GY3: 2 | GZ3: 0 | HA3: 2 | HB3: 2 | HC3: 0 | HD3: 0 | HE3: 2 | HF3: 2 | HG3: =SUM(GC3:HF3) -> 37 | HH3: =SUM(GC3+GE3+GY3+GH3+GG3+GQ3+HB3+HF3-GN3) -> 8 | HI3: =SUM(GO3+GJ3+GK3+GM3+GW3+GL3+HF3+GX3+HC3-GD3) -> 9 | HJ3: =SUM(GP3+HA3+GZ3+GD3+GN3+GU3+HB3+HC3+HE3+GY3) -> 11 | HK3: =SUM(HD3+GF3+GI3+GX3+GG3+GL3+GT3+HF3) -> 10 | HL3: =SUM(GR3+GV3+GS3+GT3+GH3+GQ3+HE3+HF3) -> 16 | HM3: 2 | HN3: 0 | HO3: 1 | HP3: 0 | HQ3: 0 | HR3: 0 | HS3: 0 | HT3: 0 | HU3: 0 | HV3: 0 | HW3: 0 | HX3: 0 | HY3: 0 | HZ3: 0 | IA3: 0 | IB3: 0 | IC3: 0 | ID3: 0 | IE3: 0 | IF3: 0 | IG3: 2 | IH3: CCC | II3: CCC | IJ3: CCC | IK3: CCC | IL3: CCC | IM3: CCC | IN3: CCC | IO3: CCC | IP3: CCC | IQ3: CCC | IR3: CCC | IS3: CCC | IT3: CCC | IU3: AAA | IV3: AAA | IW3: AAA | IX3: AAA | IY3: 1 | IZ3: 1 | JA3: 0 | JB3: 1 | JC3: =(Foglio1!$IY3+Foglio1!$IZ3+Foglio1!$JA3+Foglio1!$JB3)/4 -> 0.75 | JD3: 1 | JE3: 1 | JF3: 1 | JG3: 1 | JH3: le opere d'arte sono considerate patrimonio dell'unesco | JI3: 0 | JJ3: se riesce a rimanere aperto più ore magari si possono turnare delle persone | JK3: 0 | JL3: =(Foglio1!$JD3+Foglio1!$JE3+Foglio1!$JF3+Foglio1!$JG3+Foglio1!$JI3+Foglio1!$JK3)/6 -> 0.66666667 | JM3: 0 | JN3: 1 | JO3: 0 | JP3: =(Foglio1!$JM3+Foglio1!$JN3+Foglio1!$JO3)/3 -> 0.33333333 | JQ3: 0 | JR3: 0 | JS3: =(Foglio1!$JQ3+Foglio1!$JR3)/2 -> 0 | JT3: perseguitano le persone affinché scrivono cose anche non vere su certi argomenti | JU3: 0 | JV3: io mi arrabbio mi arrabbio ma poi mi quieto, sono così | JW3: 0 | JX3: può essere così oppure in modo diverso, visto in determinate prospettive | JY3: 0 | JZ3: =(Foglio1!$JU3+Foglio1!$JW3+Foglio1!$JY3)/3 -> 0 | KA3: =(Foglio1!$JC3) -> 0.75 | KB3: =(Foglio1!$JL3+Foglio1!$JP3+Foglio1!$JS3+Foglio1!$JZ3)/4 -> 0.25 | KC3: =(Foglio1!$JC3+Foglio1!$JL3+Foglio1!$JP3+Foglio1!$JS3+Foglio1!$JZ3)/5 -> 0.35 | KD3: sono un po' variabili | KE3: 2 | KF3: 2 | KG3: sono un po' chiuse, spinose ma se riescono a trovare qualcuno dolce che le convince ad aprirsi riescono a risolvere poblemmi | KH3: 1 | KI3: 3 | KJ3: dovrebbero sorreggere la vecchiaia dei propri genitori | KK3: 2 | KL3: 2 | KM3: qualcosa di magico, fantasioso anche | KN3: 0 | KO3: 0 | KP3: sono veramente amici che ti sorreggono in momenti difficili | KQ3: 2 | KR3: 3 | KS3: sono lenti nei movimenti ma hanno la saggezza di tante cose | KT3: 2 | KU3: 2 | KV3: ha preso un cazzotto nell'occhio | KW3: 2 | KX3: 1 | KY3: possono vedere il mondo in varie prospettive | KZ3: 2 | LA3: 3 | LB3: sono dotati di una buona vocalità | LC3: 2 | LD3: 1 | LE3: dovrebbero essere pilastri | LF3: 0 | LG3: 0 | LH3: stanno ad oziare ma nel momento del bisogno lo fanno | LI3: 0 | LJ3: 1 | LK3: fanno tutta comunella e poi alla fine decidono tutto loro | LL3: 0 | LM3: 2 | LN3: cicciottelli da schiacciare | LO3: 2 | LP3: 1 | LQ3: tante indicazioni sul futuro dello studio dopo le medie | LR3: 1 | LS3: 2 | LT3: =(Foglio1!$KE3+Foglio1!$KH3+Foglio1!$KK3+Foglio1!$KN3+Foglio1!$KQ3+Foglio1!$KT3+Foglio1!$KW3+Foglio1!$KZ3+Foglio1!$LC3+Foglio1!$LF3+Foglio1!$LI3+Foglio1!$LL3+Foglio1!$LO3+Foglio1!$LR3) -> 18 | LU3: =(Foglio1!$KI3+Foglio1!$KF3+Foglio1!$KL3+Foglio1!$KO3+Foglio1!$KR3+Foglio1!$KU3+Foglio1!$KX3+Foglio1!$LA3+Foglio1!$LD3+Foglio1!$LG3+Foglio1!$LJ3+Foglio1!$LM3+Foglio1!$LP3+Foglio1!$LS3) -> 23 | LV3: 14 | LW3: 21 | LX3: 8 | LY3: 22 | LZ3: 0 | MA3: 0 | MB3: 2 | MC3: 0 | MD3: =SUM(LZ3:MC3) -> 2 | ME3: 0 | MF3: 0 | MG3: 0 | MH3: 0 | MI3: =SUM(ME3:MH3) -> 0
A4: f31729fad7196a97 | B4: 36 | C4: F | D4: 5 | E4: 0 | F4: No | G4: BBB | H4: AAA | L4: BBB | M4: AAA | N4: AAA | O4: AAA | P4: AAA | Q4: CCC | AH4: AAA | AI4: AAA | AJ4: AAA | AK4: AAA | AL4: AAA | AM4: AAA | AN4: AAA | AO4: AAA | AP4: AAA | AQ4: AAA | AR4: AAA | AS4: AAA | AT4: AAA | AU4: AAA | AV4: AAA | AW4: AAA | AX4: AAA | AZ4: AAA | BA4: AAA | BG4: AAA | BH4: BBB | BI4: BBB | BJ4: BBB | BK4: BBB | BL4: BBB | BM4: BBB | BN4: BBB | BO4: BBB | BP4: 0 | BQ4: 0 | BR4: 0 | BS4: AAA | BT4: AAA | BU4: AAA | BV4: AAA | BW4: AAA | BX4: AAA | BY4: AAA | BZ4: AAA | CA4: AAA | CB4: AAA | CC4: AAA | CD4: AAA | CE4: AAA | CF4: AAA | CG4: AAA | CH4: AAA | CI4: AAA | CJ4: AAA | CK4: AAA | CL4: AAA | CM4: AAA | CN4: AAA | CO4: AAA | CP4: AAA | CQ4: AAA | CR4: AAA | CS4: AAA | CT4: AAA | CU4: AAA | CV4: AAA | CW4: AAA | CX4: =SUM(Foglio1!$BT4:$CW4) -> 0 | CY4: =SUM(Foglio1!$BT4+Foglio1!$BV4+Foglio1!$CP4+Foglio1!$BY4+Foglio1!$BX4+Foglio1!$CH4+Foglio1!$CS4+Foglio1!$CW4-Foglio1!$CE4) -> #VALUE! | CZ4: =SUM(Foglio1!$CF4+Foglio1!$CA4+Foglio1!$CB4+Foglio1!$CD4+Foglio1!$CN4+Foglio1!$CC4+Foglio1!$CW4+Foglio1!$CO4+Foglio1!$CT4-Foglio1!$BU4) -> #VALUE! | DA4: =SUM(Foglio1!$CG4+Foglio1!$CR4+Foglio1!$CQ4+Foglio1!$BU4+Foglio1!$CE4+Foglio1!$CL4+Foglio1!$CS4+Foglio1!$CT4+Foglio1!$CV4+Foglio1!$CP4) -> #VALUE! | DB4: =SUM(Foglio1!$CU4+Foglio1!$BW4+Foglio1!$BZ4+Foglio1!$CO4+Foglio1!$BX4+Foglio1!$CC4+Foglio1!$CK4+Foglio1!$CW4) -> #VALUE! | DC4: =SUM(Foglio1!$CI4+Foglio1!$CM4+Foglio1!$CJ4+Foglio1!$CK4+Foglio1!$BY4+Foglio1!$CH4+Foglio1!$CV4+Foglio1!$CW4) -> #VALUE! | DD4: 3 | DE4: 3 | DF4: 3 | DG4: 1 | DH4: 0 | DI4: 0 | DJ4: 2 | DK4: 0 | DL4: 0 | DM4: 0 | DN4: 0 | DO4: 0 | DP4: 0 | DQ4: 0 | DR4: 0 | DS4: 0 | DT4: 3 | DU4: 0 | DV4: 0 | DW4: 0 | DX4: 1 | DY4: 0 | DZ4: 0 | EA4: 0 | EB4: 0 | EC4: 0 | ED4: 0 | EE4: 0 | EF4: 0 | EG4: 0 | EH4: =(Foglio1!$DE4+Foglio1!$DH4+Foglio1!$DG4+Foglio1!$DF4+Foglio1!$DM4+Foglio1!$DD4+Foglio1!$DO4+Foglio1!$DL4+Foglio1!$DN4+Foglio1!$DQ4+Foglio1!$DP4+Foglio1!$DT4+Foglio1!$DI4+Foglio1!$DK4+Foglio1!$DU4) -> 13 | EI4: =(Foglio1!$EA4+Foglio1!$EB4+Foglio1!$EE4+Foglio1!$EC4+Foglio1!$ED4+Foglio1!$DZ4+Foglio1!$DY4) -> 0 | EJ4: =(Foglio1!$DW4+Foglio1!$DV4+Foglio1!$DX4) -> 1 | EK4: =(Foglio1!$EG4+Foglio1!$EF4) -> 0 | EL4: 1 | EM4: 1 | EN4: 0 | EO4: 1 | EP4: {=SUM(EL4:EO4/4)} -> 0.75 | EQ4: 1 | ER4: 0 | ES4: 0 | ET4: 0 | EU4: AAA | EV4: 0 | EW4: AAA | EX4: 0 | EY4: =(Foglio1!$EQ4+Foglio1!$ER4+Foglio1!$ES4+Foglio1!$ET4+Foglio1!$EV4+Foglio1!$EX4)/6 -> 0.16666667 | EZ4: 0 | FA4: 0 | FB4: 0 | FC4: =(Foglio1!$EZ4+Foglio1!$FA4+Foglio1!$FB4)/3 -> 0 | FD4: 0 | FE4: 0 | FF4: =(Foglio1!$FD4+Foglio1!$FE4)/2 -> 0 | FG4: AAA | FH4: 0 | FI4: AAA | FJ4: 0 | FK4: AAA | FL4: 0 | FM4: =(Foglio1!$FH4+Foglio1!$FJ4+Foglio1!$FL4)/3 -> 0 | FN4: =(Foglio1!$EP4) -> 0.75 | FO4: =(Foglio1!$EY4+Foglio1!$FC4+Foglio1!$FF4+Foglio1!$FM4)/4 -> 0.041666667 | FP4: =(Foglio1!$EP4+Foglio1!$EY4+Foglio1!$FC4+Foglio1!$FF4+Foglio1!$FM4)/5 -> 0.18333333 | FR4: AAA | FS4: AAA | FT4: AAA | FU4: AAA | FV4: AAA | FW4: AAA | FX4: AAA | FY4: AAA | FZ4: AAA | GA4: AAA | GB4: AAA | GC4: AAA | GD4: AAA | GE4: AAA | GF4: AAA | GG4: AAA | GH4: AAA | GI4: AAA | GJ4: AAA | GK4: AAA | GL4: AAA | GM4: AAA | GN4: AAA | GO4: AAA | GP4: AAA | GQ4: AAA | GR4: AAA | GS4: AAA | GT4: AAA | GU4: AAA | GV4: AAA | GW4: AAA | GX4: AAA | GY4: AAA | GZ4: AAA | HA4: AAA | HB4: AAA | HC4: AAA | HD4: AAA | HE4: AAA | HF4: AAA | HG4: AAA | HH4: AAA | HI4: AAA | HJ4: AAA | HK4: AAA | HL4: AAA | HM4: BBB | HN4: BBB | HO4: BBB | HP4: BBB | HQ4: BBB | HR4: BBB | HS4: BBB | HT4: BBB | HU4: BBB | HV4: BBB | HW4: BBB | HX4: BBB | HY4: BBB | HZ4: BBB | IA4: BBB | IB4: BBB | IC4: BBB | ID4: BBB | IE4: BBB | IF4: BBB | IG4: BBB | IH4: BBB | II4: BBB | IJ4: BBB | IK4: BBB | IL4: BBB | IM4: BBB | IN4: BBB | IO4: BBB | IP4: BBB | IQ4: BBB | IR4: BBB | IS4: BBB | IT4: BBB | IU4: BBB | IV4: BBB | IW4: BBB | IX4: BBB | IY4: BBB | IZ4: BBB | JA4: BBB | JB4: BBB | JC4: BBB | JD4: BBB | JE4: BBB | JF4: BBB | JG4: BBB | JH4: BBB | JI4: BBB | JJ4: BBB | JK4: BBB | JL4: BBB | JM4: BBB | JN4: BBB | JO4: BBB | JP4: BBB | JQ4: BBB | JR4: BBB | JS4: BBB | JT4: BBB | JU4: BBB | JV4: BBB | JW4: BBB | JX4: BBB | JY4: BBB | JZ4: BBB | KA4: BBB | KB4: BBB | KC4: BBB | KD4: BBB | KE4: BBB | KF4: BBB | KG4: BBB | KH4: BBB | KI4: BBB | KJ4: BBB | KK4: BBB | KL4: BBB | KM4: BBB | KN4: BBB | KO4: BBB | KP4: BBB | KQ4: BBB | KR4: BBB | KS4: BBB | KT4: BBB | KU4: BBB | KV4: BBB | KW4: BBB | KX4: BBB | KY4: BBB | KZ4: BBB | LA4: BBB | LB4: BBB | LC4: BBB | LD4: BBB | LE4: BBB | LF4: BBB | LG4: BBB | LH4: BBB | LI4: BBB | LJ4: BBB | LK4: BBB | LL4: BBB | LM4: BBB | LN4: BBB | LO4: BBB | LP4: BBB | LQ4: BBB | LR4: BBB | LS4: BBB | LT4: BBB | LU4: BBB | LV4: BBB | LW4: BBB | LX4: BBB | LY4: BBB | LZ4: 0 | MA4: 1 | MB4: 1 | MC4: 0 | MD4: =SUM(LZ4:MC4) -> 2 | ME4: 0 | MF4: 2 | MG4: 0 | MH4: 0 | MI4: =SUM(ME4:MH4) -> 2
A5: 724b87d338f7d91f | B5: 41 | C5: M | D5: 13 | E5: 1 | F5: Yes | G5: Somatic | H5: 296.82 Disturbo depressivo atipico | I5: (296.82) Disturbo depressivo atipico | J5: (301.9) Disturbo di personalita' non specificato | K5: (305.02) Abuso di alcool, episodico | L5: 301.9 Disturbo di personalita' non specificato | M5: Affective disorders | N5: Pensieri autolesivi e polarizzazione dell'attenzione su aspetti somatici | O5: 45451 | P5: 45470 | Q5: Sindrome depressiva atipica | R5: NA | S5: NA | T5: Sì | U5: Alcool | V5: Amisulpride | W5: Mirtazapina | X5: Venlafaxina | Y5: Delorazepam | Z5: Zolpidem | AA5: Idrossina | AB5: Gabapentin | AC5: Docixilina | AD5: Finasteride | AE5: Gentamicina | AH5: Mirtazapina | AI5: 15mg cp h 20 | AJ5: Amisulpride | AK5: 200mg cp h 20 | AL5: Gabapentin | AM5: 200mg cp h 20 | AN5: BBB | AO5: BBB | AP5: BBB | AQ5: BBB | AR5: BBB | AS5: BBB | AT5: BBB | AU5: BBB | AV5: BBB | AW5: BBB | AX5: 3 | AZ5: No | BA5: =(P5-O5) -> 19 | BB5: 0 | BC5: No | BD5: Viso e corpo ricoperti da foruncoli | BE5: No | BF5: NA | BG5: 45460 | BH5: 4 | BI5: 1 | BJ5: 3 | BK5: 3 | BL5: 4 | BM5: 4 | BN5: 0 | BO5: =SUM(Foglio1!$BH5:$BM5) -> 19 | BP5: 4 | BQ5: 2 | BR5: 5 | BS5: 41 | BT5: 3 | BU5: 1 | BV5: 3 | BW5: 2 | BX5: 2 | BY5: 1 | BZ5: 1 | CA5: 1 | CB5: 1 | CC5: 2 | CD5: 3 | CE5: 3 | CF5: 2 | CG5: 3 | CH5: 6 | CI5: 4 | CJ5: 2 | CK5: 3 | CL5: 2 | CM5: 2 | CN5: 1 | CO5: 1 | CP5: 4 | CQ5: 1 | CR5: 3 | CS5: 3 | CT5: 2 | CU5: 1 | CV5: 5 | CW5: 3 | CX5: =SUM(Foglio1!$BT5:$CW5) -> 71 | CY5: =SUM(Foglio1!$BT5+Foglio1!$BV5+Foglio1!$CP5+Foglio1!$BY5+Foglio1!$BX5+Foglio1!$CH5+Foglio1!$CS5+Foglio1!$CW5-Foglio1!$CE5) -> 22 | CZ5: =SUM(Foglio1!$CF5+Foglio1!$CA5+Foglio1!$CB5+Foglio1!$CD5+Foglio1!$CN5+Foglio1!$CC5+Foglio1!$CW5+Foglio1!$CO5+Foglio1!$CT5-Foglio1!$BU5) -> 15 | DA5: =SUM(Foglio1!$CG5+Foglio1!$CR5+Foglio1!$CQ5+Foglio1!$BU5+Foglio1!$CE5+Foglio1!$CL5+Foglio1!$CS5+Foglio1!$CT5+Foglio1!$CV5+Foglio1!$CP5) -> 27 | DB5: =SUM(Foglio1!$CU5+Foglio1!$BW5+Foglio1!$BZ5+Foglio1!$CO5+Foglio1!$BX5+Foglio1!$CC5+Foglio1!$CK5+Foglio1!$CW5) -> 15 | DC5: =SUM(Foglio1!$CI5+Foglio1!$CM5+Foglio1!$CJ5+Foglio1!$CK5+Foglio1!$BY5+Foglio1!$CH5+Foglio1!$CV5+Foglio1!$CW5) -> 26 | DD5: 1 | DE5: 0 | DF5: 0 | DG5: 0 | DH5: 0 | DI5: 2 | DJ5: 0 | DK5: 0 | DL5: 0 | DM5: 0 | DN5: 0 | DO5: 0 | DP5: 0 | DQ5: 0 | DR5: 0 | DS5: 0 | DT5: 0 | DU5: 2 | DV5: 0 | DW5: 0 | DX5: 1 | DY5: CCC | DZ5: CCC | EA5: CCC | EB5: CCC | EC5: CCC | ED5: CCC | EE5: CCC | EF5: CCC | EG5: CCC | EH5: =(Foglio1!$DE5+Foglio1!$DH5+Foglio1!$DG5+Foglio1!$DF5+Foglio1!$DM5+Foglio1!$DD5+Foglio1!$DO5+Foglio1!$DL5+Foglio1!$DN5+Foglio1!$DQ5+Foglio1!$DP5+Foglio1!$DT5+Foglio1!$DI5+Foglio1!$DK5+Foglio1!$DU5) -> 5 | EI5: =(Foglio1!$EA5+Foglio1!$EB5+Foglio1!$EE5+Foglio1!$EC5+Foglio1!$ED5+Foglio1!$DZ5+Foglio1!$DY5) -> #VALUE! | EJ5: =(Foglio1!$DW5+Foglio1!$DV5+Foglio1!$DX5) -> 1 | EK5: =(Foglio1!$EG5+Foglio1!$EF5) -> #VALUE! | EL5: 1 | EM5: 0 | EN5: 1 | EO5: 0 | EP5: {=SUM(EL5:EO5/4)} -> 0.5 | EQ5: 1 | ER5: 1 | ES5: 0 | ET5: 1 | EU5: non va bene che il cinghiale giri nel centro della città | EV5: 0 | EW5: prendere provvedimenti | EX5: 1 | EY5: =(Foglio1!$EQ5+Foglio1!$ER5+Foglio1!$ES5+Foglio1!$ET5+Foglio1!$EV5+Foglio1!$EX5)/6 -> 0.66666667 | EZ5: 1 | FA5: 1 | FB5: 1 | FC5: =(Foglio1!$EZ5+Foglio1!$FA5+Foglio1!$FB5)/3 -> 1 | FD5: 1 | FE5: 0 | FF5: =(Foglio1!$FD5+Foglio1!$FE5)/2 -> 0.5 | FG5: ci sono libri che possono darti tanto | FH5: 1 | FI5: se uno trova dei soldi è avido e può rubarli | FJ5: 0 | FK5: non bisogna solo mangiare ma anche lavorare nella vita | FL5: 0 | FM5: =(Foglio1!$FH5+Foglio1!$FJ5+Foglio1!$FL5)/3 -> 0.33333333 | FN5: =(Foglio1!$EP5) -> 0.5 | FO5: =(Foglio1!$EY5+Foglio1!$FC5+Foglio1!$FF5+Foglio1!$FM5)/4 -> 0.625 | FP5: =(Foglio1!$EP5+Foglio1!$EY5+Foglio1!$FC5+Foglio1!$FF5+Foglio1!$FM5)/5 -> 0.6 | FQ5: 45468 | FR5: 2 | FS5: 2 | FT5: 2 | FU5: 2 | FV5: 1 | FW5: 0 | FX5: 0 | FY5: 4 | FZ5: 2 | GA5: 5 | GB5: 51 | GC5: 1 | GD5: 0 | GE5: 0 | GF5: 2 | GG5: 0 | GH5: 0 | GI5: 0 | GJ5: 1 | GK5: 0 | GL5: 0 | GM5: 0 | GN5: 2 | GO5: 2 | GP5: 3 | GQ5: 2 | GR5: 1 | GS5: 0 | GT5: 2 | GU5: 2 | GV5: 2 | GW5: 0 | GX5: 0 | GY5: 1 | GZ5: 0 | HA5: 0 | HB5: 1 | HC5: 1 | HD5: 0 | HE5: 1 | HF5: 0 | HG5: =SUM(GC5:HF5) -> 24 | HH5: =SUM(GC5+GE5+GY5+GH5+GG5+GQ5+HB5+HF5-GN5) -> 3 | HI5: =SUM(GO5+GJ5+GK5+GM5+GW5+GL5+HF5+GX5+HC5-GD5) -> 4 | HJ5: =SUM(GP5+HA5+GZ5+GD5+GN5+GU5+HB5+HC5+HE5+GY5) -> 11 | HK5: =SUM(HD5+GF5+GI5+GX5+GG5+GL5+GT5+HF5) -> 4 | HL5: =SUM(GR5+GV5+GS5+GT5+GH5+GQ5+HE5+HF5) -> 8 | HM5: 0 | HN5: 0 | HO5: 0 | HP5: 0 | HQ5: 0 | HR5: 0 | HS5: 0 | HT5: 0 | HU5: 0 | HV5: 0 | HW5: 0 | HX5: 0 | HY5: 0 | HZ5: 0 | IA5: 0 | IB5: 0 | IC5: 0 | ID5: 0 | IE5: 0 | IF5: 0 | IG5: 2 | IH5: CCC | II5: CCC | IJ5: CCC | IK5: CCC | IL5: CCC | IM5: CCC | IN5: CCC | IO5: CCC | IP5: CCC | IQ5: CCC | IR5: CCC | IS5: CCC | IT5: CCC | IU5: AAA | IV5: AAA | IW5: AAA | IX5: AAA | IY5: 1 | IZ5: 0 | JA5: 1 | JB5: 1 | JC5: =(Foglio1!$IY5+Foglio1!$IZ5+Foglio1!$JA5+Foglio1!$JB5)/4 -> 0.75 | JD5: 1 | JE5: 0 | JF5: 1 | JG5: 1 | JH5: è una cosa bellissima, una rarità | JI5: 1 | JJ5: non è così che si risolve, invec di assumere prende lui gli assessori | JK5: 1 | JL5: =(Foglio1!$JD5+Foglio1!$JE5+Foglio1!$JF5+Foglio1!$JG5+Foglio1!$JI5+Foglio1!$JK5)/6 -> 0.83333333 | JM5: 0 | JN5: 1 | JO5: 1 | JP5: =(Foglio1!$JM5+Foglio1!$JN5+Foglio1!$JO5)/3 -> 0.66666667 | JQ5: 1 | JR5: 0 | JS5: =(Foglio1!$JQ5+Foglio1!$JR5)/2 -> 0.5 | JT5: sono come avvoltoi che vogliono prendere casi più importanti e sono lì a mangiarsi l'uno con l'altro per accaparrarsi il caso | JU5: 1 | JV5: il cane che abbia e basta non morde di solito, come il mio cane | JW5: 0 | JX5: non è una cosa bella, uno che ha avuto una medaglia è stato in guerra, non ha passato dei bei momenti, non è così bello ricevere una medaglia | JY5: 0 | JZ5: =(Foglio1!$JU5+Foglio1!$JW5+Foglio1!$JY5)/3 -> 0.33333333 | KA5: =(Foglio1!$JC5) -> 0.75 | KB5: =(Foglio1!$JL5+Foglio1!$JP5+Foglio1!$JS5+Foglio1!$JZ5)/4 -> 0.58333333 | KC5: =(Foglio1!$JC5+Foglio1!$JL5+Foglio1!$JP5+Foglio1!$JS5+Foglio1!$JZ5)/5 -> 0.61666667 | KD5: sono fannulloni, non hanno voglia di lavorare, fare nulla come i nostri genitori | KE5: 0 | KF5: 2 | KG5: sono puntigliose su alcune cose da fare, difficile da starci insieme | KH5: 0 | KI5: 3 | KJ5: aiutano i genitori | KK5: 2 | KL5: 2 | KM5: è bellissima | KN5: 0 | KO5: 1 | KP5: ti puoi fidare, puoi rivelare tutti i tuoi segreti | KQ5: 2 | KR5: 2 | KS5: sono lenti in tutto | KT5: 2 | KU5: 1 | KV5: è lento come un panda | KW5: 1 | KX5: 1 | KY5: sanno talmente tante cose che volano al di sopra delle altre persone | KZ5: 2 | LA5: 3 | LB5: cantano meglio di altri | LC5: 2 | LD5: 1 | LE5: sono colonne portanti della famiglia | LF5: 1 | LG5: 2 | LH5: stanno sempre al sole | LI5: 2 | LJ5: 1 | LK5: non fanno niente, si riempiono di soldi e aprono la coda come i pavoni | LL5: 1 | LM5: 2 | LN5: bellissimi, da coccolare | LO5: 1 | LP5: 1 | LQ5: possono illuminare sul percorso della tua vita | LR5: 2 | LS5: 2 | LT5: =(Foglio1!$KE5+Foglio1!$KH5+Foglio1!$KK5+Foglio1!$KN5+Foglio1!$KQ5+Foglio1!$KT5+Foglio1!$KW5+Foglio1!$KZ5+Foglio1!$LC5+Foglio1!$LF5+Foglio1!$LI5+Foglio1!$LL5+Foglio1!$LO5+Foglio1!$LR5) -> 18 | LU5: =(Foglio1!$KI5+Foglio1!$KF5+Foglio1!$KL5+Foglio1!$KO5+Foglio1!$KR5+Foglio1!$KU5+Foglio1!$KX5+Foglio1!$LA5+Foglio1!$LD5+Foglio1!$LG5+Foglio1!$LJ5+Foglio1!$LM5+Foglio1!$LP5+Foglio1!$LS5) -> 24 | LV5: 15 | LW5: 45 | LX5: 19 | LY5: 31 | LZ5: 0 | MA5: 0 | MB5: 1 | MC5: 1 | MD5: =SUM(LZ5:MC5) -> 2 | ME5: 1 | MF5: 2 | MG5: 0 | MH5: 0 | MI5: =SUM(ME5:MH5) -> 3
A6: 471103b474d18929 | B6: 55 | C6: F | D6: 8 | E6: 1 | F6: Yes | G6: Persecutory | H6: 297.1 Disturbo delirante | I6: (297.1) Disturbo delirante | J6: BBB | L6: BBB | M6: Schizophrenia and other psychoses | N6: Scompenso psicotico | O6: 45456 | P6: 45475 | Q6: Psicosi non specificata | R6: NA | S6: NA | T6: No | U6: NA | V6: Lurasidone | W6: Olanzapina | X6: Aloperidolo | Y6: Acido valproico | Z6: Zolpidem | AH6: Olanzapina | AI6: 300 mg/2 sett | AJ6: Acido valproico | AK6: 300 mg 1 cp h. 8-20 | AL6: Zolpidem | AM6: 5 mg 1 cp h. 22.00 | AN6: Colecalciferolo | AO6: AAA | AP6: AAA | AQ6: AAA | AR6: AAA | AS6: AAA | AT6: AAA | AU6: AAA | AV6: AAA | AW6: AAA | AX6: 4 | AZ6: No | BA6: =(P6-O6) -> 19 | BB6: 0 | BC6: No | BD6: Vicini di casa, telecamere che la spiano, presenza di un microchip nel dente | BE6: No | BF6: NA | BG6: 45463 | BH6: 3 | BI6: 3 | BJ6: 4 | BK6: 0 | BL6: 4 | BM6: 4 | BN6: 4 | BO6: =SUM(Foglio1!$BH6:$BM6) -> 18 | BP6: 4 | BQ6: 3 | BR6: 9 | BS6: 35 | BT6: 5 | BU6: 3 | BV6: 2 | BW6: 2 | BX6: 1 | BY6: 3 | BZ6: 2 | CA6: 1 | CB6: 1 | CC6: 1 | CD6: 1 | CE6: 1 | CF6: 1 | CG6: 1 | CH6: 1 | CI6: 1 | CJ6: 4 | CK6: 2 | CL6: 2 | CM6: 3 | CN6: 1 | CO6: 3 | CP6: 5 | CQ6: 1 | CR6: 1 | CS6: 5 | CT6: 2 | CU6: 2 | CV6: 3 | CW6: 3 | CX6: =SUM(Foglio1!$BT6:$CW6) -> 64 | CY6: =SUM(Foglio1!$BT6+Foglio1!$BV6+Foglio1!$CP6+Foglio1!$BY6+Foglio1!$BX6+Foglio1!$CH6+Foglio1!$CS6+Foglio1!$CW6-Foglio1!$CE6) -> 24 | CZ6: =SUM(Foglio1!$CF6+Foglio1!$CA6+Foglio1!$CB6+Foglio1!$CD6+Foglio1!$CN6+Foglio1!$CC6+Foglio1!$CW6+Foglio1!$CO6+Foglio1!$CT6-Foglio1!$BU6) -> 11 | DA6: =SUM(Foglio1!$CG6+Foglio1!$CR6+Foglio1!$CQ6+Foglio1!$BU6+Foglio1!$CE6+Foglio1!$CL6+Foglio1!$CS6+Foglio1!$CT6+Foglio1!$CV6+Foglio1!$CP6) -> 24 | DB6: =SUM(Foglio1!$CU6+Foglio1!$BW6+Foglio1!$BZ6+Foglio1!$CO6+Foglio1!$BX6+Foglio1!$CC6+Foglio1!$CK6+Foglio1!$CW6) -> 16 | DC6: =SUM(Foglio1!$CI6+Foglio1!$CM6+Foglio1!$CJ6+Foglio1!$CK6+Foglio1!$BY6+Foglio1!$CH6+Foglio1!$CV6+Foglio1!$CW6) -> 20 | DD6: 4 | DE6: 4 | DF6: 3 | DG6: 0 | DH6: 1 | DI6: 2 | DJ6: 0 | DK6: 0 | DL6: 2 | DM6: 3 | DN6: 0 | DO6: 0 | DP6: 0 | DQ6: 0 | DR6: 0 | DS6: 0 | DT6: 2 | DU6: 1 | DV6: 0 | DW6: 0 | DX6: 1 | DY6: CCC | DZ6: CCC | EA6: CCC | EB6: CCC | EC6: CCC | ED6: CCC | EE6: CCC | EF6: CCC | EG6: CCC | EH6: =(Foglio1!$DE6+Foglio1!$DH6+Foglio1!$DG6+Foglio1!$DF6+Foglio1!$DM6+Foglio1!$DD6+Foglio1!$DO6+Foglio1!$DL6+Foglio1!$DN6+Foglio1!$DQ6+Foglio1!$DP6+Foglio1!$DT6+Foglio1!$DI6+Foglio1!$DK6+Foglio1!$DU6) -> 22 | EI6: =(Foglio1!$EA6+Foglio1!$EB6+Foglio1!$EE6+Foglio1!$EC6+Foglio1!$ED6+Foglio1!$DZ6+Foglio1!$DY6) -> #VALUE! | EJ6: =(Foglio1!$DW6+Foglio1!$DV6+Foglio1!$DX6) -> 1 | EK6: =(Foglio1!$EG6+Foglio1!$EF6) -> #VALUE! | EL6: 0 | EM6: 1 | EN6: 1 | EO6: 0 | EP6: {=SUM(EL6:EO6/4)} -> 0.5 | EQ6: 1 | ER6: 0 | ES6: 0 | ET6: 0 | EU6: ironia. Dice come dire non avrà più voglia di nessuno di venire in città. | EV6: 1 | EW6: prenda provvedimenti | EX6: 1 | EY6: =(Foglio1!$EQ6+Foglio1!$ER6+Foglio1!$ES6+Foglio1!$ET6+Foglio1!$EV6+Foglio1!$EX6)/6 -> 0.5 | EZ6: 1 | FA6: 1 | FB6: 1 | FC6: =(Foglio1!$EZ6+Foglio1!$FA6+Foglio1!$FB6)/3 -> 1 | FD6: 1 | FE6: 1 | FF6: =(Foglio1!$FD6+Foglio1!$FE6)/2 -> 1 | FG6: i libri sono una cosa importante | FH6: 0 | FI6: se ti capita l'opportunità diventi ladro anche se non lo sei | FJ6: 1 | FK6: non si vive solo di cose materiali ma anche di sentimenti, emozioni | FL6: 1 | FM6: =(Foglio1!$FH6+Foglio1!$FJ6+Foglio1!$FL6)/3 -> 0.66666667 | FN6: =(Foglio1!$EP6) -> 0.5 | FO6: =(Foglio1!$EY6+Foglio1!$FC6+Foglio1!$FF6+Foglio1!$FM6)/4 -> 0.79166667 | FP6: =(Foglio1!$EP6+Foglio1!$EY6+Foglio1!$FC6+Foglio1!$FF6+Foglio1!$FM6)/5 -> 0.73333333 | FQ6: 45474 | FR6: 3 | FS6: 0 | FT6: 1 | FU6: 3 | FV6: 3 | FW6: 2 | FX6: 3 | FY6: 4 | FZ6: 0 | GA6: 0 | GB6: 45 | GC6: 4 | GD6: 1 | GE6: 0 | GF6: 2 | GG6: 0 | GH6: 4 | GI6: 0 | GJ6: 0 | GK6: 0 | GL6: 0 | GM6: 2 | GN6: 1 | GO6: 0 | GP6: 0 | GQ6: 0 | GR6: 2 | GS6: 4 | GT6: 2 | GU6: 0 | GV6: 1 | GW6: 0 | GX6: 0 | GY6: 4 | GZ6: 0 | HA6: 0 | HB6: 4 | HC6: 0 | HD6: 0 | HE6: 2 | HF6: 4 | HG6: =SUM(GC6:HF6) -> 37 | HH6: =SUM(GC6+GE6+GY6+GH6+GG6+GQ6+HB6+HF6-GN6) -> 19 | HI6: =SUM(GO6+GJ6+GK6+GM6+GW6+GL6+HF6+GX6+HC6-GD6) -> 5 | HJ6: =SUM(GP6+HA6+GZ6+GD6+GN6+GU6+HB6+HC6+HE6+GY6) -> 12 | HK6: =SUM(HD6+GF6+GI6+GX6+GG6+GL6+GT6+HF6) -> 8 | HL6: =SUM(GR6+GV6+GS6+GT6+GH6+GQ6+HE6+HF6) -> 19 | HM6: 3 | HN6: 3 | HO6: 3 | HP6: 1 | HQ6: 2 | HR6: 2 | HS6: 0 | HT6: 0 | HU6: 2 | HV6: 2 | HW6: 0 | HX6: 0 | HY6: 0 | HZ6: 0 | IA6: 0 | IB6: 0 | IC6: 0 | ID6: 2 | IE6: 0 | IF6: 0 | IG6: 0 | IH6: CCC | II6: CCC | IJ6: CCC | IK6: CCC | IL6: CCC | IM6: CCC | IN6: CCC | IO6: CCC | IP6: CCC | IQ6: CCC | IR6: CCC | IS6: CCC | IT6: CCC | IU6: AAA | IV6: AAA | IW6: AAA | IX6: AAA | IY6: 0 | IZ6: 1 | JA6: 1 | JB6: 1 | JC6: =(Foglio1!$IY6+Foglio1!$IZ6+Foglio1!$JA6+Foglio1!$JB6)/4 -> 0.75 | JD6: 1 | JE6: 1 | JF6: 1 | JG6: 1 | JH6: ha molte cose che valgono | JI6: 1 | JJ6: ironico | JK6: 1 | JL6: =(Foglio1!$JD6+Foglio1!$JE6+Foglio1!$JF6+Foglio1!$JG6+Foglio1!$JI6+Foglio1!$JK6)/6 -> 1 | JM6: 1 | JN6: 1 | JO6: 1 | JP6: =(Foglio1!$JM6+Foglio1!$JN6+Foglio1!$JO6)/3 -> 1 | JQ6: 0 | JR6: 0 | JS6: =(Foglio1!$JQ6+Foglio1!$JR6)/2 -> 0 | JT6: usano quello che succede per ingigantire le cose | JU6: 0 | JV6: a volte le persone che parlano tanto non fanno del male | JW6: 1 | JX6: ci sono sempre i pro e i contro nelle cose | JY6: 1 | JZ6: =(Foglio1!$JU6+Foglio1!$JW6+Foglio1!$JY6)/3 -> 0.66666667 | KA6: =(Foglio1!$JC6) -> 0.75 | KB6: =(Foglio1!$JL6+Foglio1!$JP6+Foglio1!$JS6+Foglio1!$JZ6)/4 -> 0.66666667 | KC6: =(Foglio1!$JC6+Foglio1!$JL6+Foglio1!$JP6+Foglio1!$JS6+Foglio1!$JZ6)/5 -> 0.68333333 | KD6: oscillano da una parte all'altra | KE6: 1 | KF6: 1 | KG6: magre | KH6: 1 | KI6: 1 | KJ6: quando sei in difficoltà puoi contare su di loro | KK6: 2 | KL6: 2 | KM6: è vestita di bianco | KN6: 1 | KO6: 1 | KP6: ti ci puoi aggrappare | KQ6: 1 | KR6: 2 | KS6: vanno pianino | KT6: 2 | KU6: 1 | KV6: (non risponde) | KW6: 0 | KX6: 0 | KY6: vedono le cose dall'alto | KZ6: 1 | LA6: 2 | LB6: cantano bene | LC6: 2 | LD6: 1 | LE6: aiutano nella crescita i nipoti | LF6: 2 | LG6: 2 | LH6: sono sempre al sole | LI6: 2 | LJ6: 1 | LK6: si fanno vedere | LL6: 2 | LM6: 2 | LN6: sono carini | LO6: 2 | LP6: 1 | LQ6: sono bravi e aiutano gli alunni a vedere la vita | LR6: 1 | LS6: 2 | LT6: =(Foglio1!$KE6+Foglio1!$KH6+Foglio1!$KK6+Foglio1!$KN6+Foglio1!$KQ6+Foglio1!$KT6+Foglio1!$KW6+Foglio1!$KZ6+Foglio1!$LC6+Foglio1!$LF6+Foglio1!$LI6+Foglio1!$LL6+Foglio1!$LO6+Foglio1!$LR6) -> 20 | LU6: =(Foglio1!$KI6+Foglio1!$KF6+Foglio1!$KL6+Foglio1!$KO6+Foglio1!$KR6+Foglio1!$KU6+Foglio1!$KX6+Foglio1!$LA6+Foglio1!$LD6+Foglio1!$LG6+Foglio1!$LJ6+Foglio1!$LM6+Foglio1!$LP6+Foglio1!$LS6) -> 19 | LV6: 31 | LW6: 40 | LX6: 19 | LY6: 31 | LZ6: 0 | MA6: 18 | MB6: 9 | MC6: 1 | MD6: =SUM(LZ6:MC6) -> 28 | ME6: 0 | MF6: 0 | MG6: 0 | MH6: 0 | MI6: =SUM(ME6:MH6) -> 0
A7: cbdb310585de2ab8 | B7: 54 | C7: M | D7: 8 | E7: 1 | F7: Yes | G7: Bizarre | H7: 295.74 Disturbo schizo-affettivo, cronico con esacerbazione acuta | I7: (295.74) Disturbo schizo-affettivo, cronico con esacerbazione acuta | J7: BBB | L7: BBB | M7: Affective disorders | N7: Scompenso psicotico | O7: 45472 | P7: 45490 | Q7: Disturbo schizoaffettivo | V7: Paliperidone palmitato | W7: Aloperidolo | X7: Busedonide/formoterolo | Y7: Metformina | Z7: Insulina glargine | AH7: Olanzapina | AI7: cp 20 mg ore 20 | AJ7: Ramipril | AK7: cp 2,5 mg ore 20 | AL7: Levotiroxina | AM7: cp 75 ug ore 7 (da lunedì a venerdì), 100 ug ore 7 (sabato e domenica) | AN7: Empaglifozin/linagliptin | AO7: cp 25/5 mg ore 12 | AP7: Metformina | AQ7: cp 1000 mg ore 8-12-19 (ai pasti) | AR7: Atorvastatina | AS7: cp 10 mg ore 20 | AT7: Ins Glargine | AU7: sol 10 UI s.c. ore 22 | AV7: Budesonide/formoterolo | AW7: 160/4,5 ug 2 puff inalatori ore 8-2 | AX7: 8 | AZ7: AAA | BA7: =(P7-O7) -> 18 | BB7: ccc | BC7: ccc | BD7: Il comandante della fogore gli da ordini | BE7: CCC | BF7: CCC | BG7: 45475 | BH7: 4 | BI7: 3 | BJ7: 4 | BK7: 4 | BL7: 4 | BM7: 4 | BN7: 3 | BO7: =SUM(Foglio1!$BH7:$BM7) -> 23 | BP7: 7 | BQ7: 3 | BR7: 10 | BS7: 35 | BT7: 6 | BU7: 3 | BV7: 6 | BW7: 2 | BX7: 3 | BY7: 2 | BZ7: 1 | CA7: 1 | CB7: 2 | CC7: 1 | CD7: 1 | CE7: 5 | CF7: 1 | CG7: 1 | CH7: 1 | CI7: 1 | CJ7: 1 | CK7: 1 | CL7: 1 | CM7: 1 | CN7: 1 | CO7: 1 | CP7: 6 | CQ7: 2 | CR7: 1 | CS7: 6 | CT7: 1 | CU7: 1 | CV7: 1 | CW7: 1 | CX7: =SUM(Foglio1!$BT7:$CW7) -> 62 | CY7: =SUM(Foglio1!$BT7+Foglio1!$BV7+Foglio1!$CP7+Foglio1!$BY7+Foglio1!$BX7+Foglio1!$CH7+Foglio1!$CS7+Foglio1!$CW7-Foglio1!$CE7) -> 26 | CZ7: =SUM(Foglio1!$CF7+Foglio1!$CA7+Foglio1!$CB7+Foglio1!$CD7+Foglio1!$CN7+Foglio1!$CC7+Foglio1!$CW7+Foglio1!$CO7+Foglio1!$CT7-Foglio1!$BU7) -> 7 | DA7: =SUM(Foglio1!$CG7+Foglio1!$CR7+Foglio1!$CQ7+Foglio1!$BU7+Foglio1!$CE7+Foglio1!$CL7+Foglio1!$CS7+Foglio1!$CT7+Foglio1!$CV7+Foglio1!$CP7) -> 27 | DB7: =SUM(Foglio1!$CU7+Foglio1!$BW7+Foglio1!$BZ7+Foglio1!$CO7+Foglio1!$BX7+Foglio1!$CC7+Foglio1!$CK7+Foglio1!$CW7) -> 11 | DC7: =SUM(Foglio1!$CI7+Foglio1!$CM7+Foglio1!$CJ7+Foglio1!$CK7+Foglio1!$BY7+Foglio1!$CH7+Foglio1!$CV7+Foglio1!$CW7) -> 9 | DD7: 0 | DE7: 1 | DF7: 3 | DG7: 0 | DH7: 2 | DI7: 1 | DJ7: 0 | DK7: 0 | DL7: 0 | DM7: 0 | DN7: 2 | DO7: 0 | DP7: 0 | DQ7: 0 | DR7: 0 | DS7: 0 | DT7: 0 | DU7: 3 | DV7: 0 | DW7: 0 | DX7: 1 | DY7: CCC | DZ7: CCC | EA7: CCC | EB7: CCC | EC7: CCC | ED7: CCC | EE7: CCC | EF7: CCC | EG7: CCC | EH7: =(Foglio1!$DE7+Foglio1!$DH7+Foglio1!$DG7+Foglio1!$DF7+Foglio1!$DM7+Foglio1!$DD7+Foglio1!$DO7+Foglio1!$DL7+Foglio1!$DN7+Foglio1!$DQ7+Foglio1!$DP7+Foglio1!$DT7+Foglio1!$DI7+Foglio1!$DK7+Foglio1!$DU7) -> 12 | EI7: =(Foglio1!$EA7+Foglio1!$EB7+Foglio1!$EE7+Foglio1!$EC7+Foglio1!$ED7+Foglio1!$DZ7+Foglio1!$DY7) -> #VALUE! | EJ7: =(Foglio1!$DW7+Foglio1!$DV7+Foglio1!$DX7) -> 1 | EK7: =(Foglio1!$EG7+Foglio1!$EF7) -> #VALUE! | EL7: 1 | EM7: 0 | EN7: 0 | EO7: 1 | EP7: {=SUM(EL7:EO7/4)} -> 0.5 | EQ7: 0 | ER7: 1 | ES7: 0 | ET7: 1 | EU7: il popolo cinese che prima è stato boicottato dagli italiani perché volevano vendere i loro prodotti | EV7: 0 | EW7: prendano coraggio | EX7: 0 | EY7: =(Foglio1!$EQ7+Foglio1!$ER7+Foglio1!$ES7+Foglio1!$ET7+Foglio1!$EV7+Foglio1!$EX7)/6 -> 0.33333333 | EZ7: 1 | FA7: 1 | FB7: 1 | FC7: =(Foglio1!$EZ7+Foglio1!$FA7+Foglio1!$FB7)/3 -> 1 | FD7: 0 | FE7: 0 | FF7: =(Foglio1!$FD7+Foglio1!$FE7)/2 -> 0 | FG7: ognuno ha voluto dare il suo contributo nello scrivere romanzi, storie ma sempre a lieto fine | FH7: 0 | FI7: sia in fatto materiale sia in fatto sentimentale, si fregano le donne uno con l'altro e se trovano soldi li prendono | FJ7: 0 | FK7: non si può solo lavorare e basta bisogna avere anche uno svago e divertimento | FL7: 1 | FM7: =(Foglio1!$FH7+Foglio1!$FJ7+Foglio1!$FL7)/3 -> 0.33333333 | FN7: =(Foglio1!$EP7) -> 0.5 | FO7: =(Foglio1!$EY7+Foglio1!$FC7+Foglio1!$FF7+Foglio1!$FM7)/4 -> 0.41666667 | FP7: =(Foglio1!$EP7+Foglio1!$EY7+Foglio1!$FC7+Foglio1!$FF7+Foglio1!$FM7)/5 -> 0.43333333 | FQ7: 45490 | FR7: 4 | FS7: 1 | FT7: 3 | FU7: 3 | FV7: 2 | FW7: 0 | FX7: 1 | FY7: 4 | FZ7: 3 | GA7: 10 | GB7: 60 | GC7: 3 | GD7: 2 | GE7: 4 | GF7: 2 | GG7: 3 | GH7: 3 | GI7: 0 | GJ7: 0 | GK7: 0 | GL7: 2 | GM7: 0 | GN7: 3 | GO7: 0 | GP7: 2 | GQ7: 0 | GR7: 0 | GS7: 2 | GT7: 2 | GU7: 2 | GV7: 0 | GW7: 0 | GX7: 2 | GY7: 4 | GZ7: 0 | HA7: 2 | HB7: 3 | HC7: 0 | HD7: 3 | HE7: 0 | HF7: 0 | HG7: =SUM(GC7:HF7) -> 44 | HH7: =SUM(GC7+GE7+GY7+GH7+GG7+GQ7+HB7+HF7-GN7) -> 17 | HI7: =SUM(GO7+GJ7+GK7+GM7+GW7+GL7+HF7+GX7+HC7-GD7) -> 2 | HJ7: =SUM(GP7+HA7+GZ7+GD7+GN7+GU7+HB7+HC7+HE7+GY7) -> 18 | HK7: =SUM(HD7+GF7+GI7+GX7+GG7+GL7+GT7+HF7) -> 14 | HL7: =SUM(GR7+GV7+GS7+GT7+GH7+GQ7+HE7+HF7) -> 7 | HM7: 3 | HN7: 2 | HO7: 3 | HP7: 1 | HQ7: 2 | HR7: 0 | HS7: 0 | HT7: 0 | HU7: 0 | HV7: 0 | HW7: 0 | HX7: 0 | HY7: 0 | HZ7: 0 | IA7: 0 | IB7: 0 | IC7: 0 | ID7: 0 | IE7: 0 | IF7: 0 | IG7: 2 | IH7: 1 | II7: 1 | IJ7: 1 | IK7: 4 | IL7: 1 | IM7: 1 | IN7: 1 | IO7: 2 | IP7: 1 | IQ7: =SUM(HN7+HQ7+HP7+HO7+HV7+HM7+HX7+HU7+HW7+HZ7+HY7+IC7+HR7+HT7+ID7) -> 11 | IR7: =SUM(IJ7+IK7+IN7+IL7+IM7+II7+IH7) -> 10 | IS7: =SUM(IF7+IE7+IG7) -> 2 | IT7: =SUM(IP7+IO7) -> 3 | IU7: AAA | IV7: AAA | IW7: AAA | IX7: AAA | IY7: 1 | IZ7: 0 | JA7: 0 | JB7: 1 | JC7: =(Foglio1!$IY7+Foglio1!$IZ7+Foglio1!$JA7+Foglio1!$JB7)/4 -> 0.5 | JD7: 0 | JE7: 1 | JF7: 1 | JG7: 1 | JH7: è qualcosa di spettacolare | JI7: 1 | JJ7: magari non possono pagare più di tanto perché non hanno sovvenzioni governative e non hanno abbastanza volontari che possono gestire il museo | JK7: 0 | JL7: =(Foglio1!$JD7+Foglio1!$JE7+Foglio1!$JF7+Foglio1!$JG7+Foglio1!$JI7+Foglio1!$JK7)/6 -> 0.66666667 | JM7: 1 | JN7: 1 | JO7: 1 | JP7: =(Foglio1!$JM7+Foglio1!$JN7+Foglio1!$JO7)/3 -> 1 | JQ7: 0 | JR7: 0 | JS7: =(Foglio1!$JQ7+Foglio1!$JR7)/2 -> 0 | JT7: vogliono avere l'anteprima | JU7: 0 | JV7: solitamente il cane che avverte un disguido, qualcosa che non funziona è un po' un avvertimento, bisogna vedere da che taglia | JW7: 0 | JX7: ci può essere il bello ed il brutto di una medaglia | JY7: 0 | JZ7: =(Foglio1!$JU7+Foglio1!$JW7+Foglio1!$JY7)/3 -> 0 | KA7: =(Foglio1!$JC7) -> 0.5 | KB7: =(Foglio1!$JL7+Foglio1!$JP7+Foglio1!$JS7+Foglio1!$JZ7)/4 -> 0.41666667 | KC7: =(Foglio1!$JC7+Foglio1!$JL7+Foglio1!$JP7+Foglio1!$JS7+Foglio1!$JZ7)/5 -> 0.43333333 | KD7: seguono l'andamento della loro gioventù, seguono il tempo che hanno adesso | KE7: 0 | KF7: 2 | KG7: bisogna vedere se sono mature o devono ancora maturare | KH7: 1 | KI7: 2 | KJ7: una volta i genitori da grandi hanno mantenuto i figli per gli studi e alla fine sarebbero i figli che devono mantenere anche se c'è la pensione che dovrebbero curare i genitori | KK7: 2 | KL7: 2 | KM7: un pensiero | KN7: 0 | KO7: 0 | KP7: ancore di salvezza, dopo una relazione finita magari malamente gli amici sono un'ancora di salvezza | KQ7: 1 | KR7: 2 | KS7: sono corazzati | KT7: 1 | KU7: 2 | KV7: potrei prendere Damiani come pugile, non era muscoloso ma sapeva boxare | KW7: 0 | KX7: 0 | KY7: volano alto | KZ7: 1 | LA7: 2 | LB7: hanno una voce bella | LC7: 2 | LD7: 1 | LE7: la loro esperienza ci insegna a non commettere errori nel futuro | LF7: 0 | LG7: 2 | LH7: sono coccodrilli in miniatura | LI7: 0 | LJ7: 0 | LK7: sono personaggi che viaggiano in libertà vigilata, non mi piace la politica | LL7: 0 | LM7: 0 | LN7: (non risponde) | LO7: 0 | LP7: 0 | LQ7: un tipo di luminosità per leggere nella notte | LR7: 0 | LS7: 0 | LT7: =(Foglio1!$KE7+Foglio1!$KH7+Foglio1!$KK7+Foglio1!$KN7+Foglio1!$KQ7+Foglio1!$KT7+Foglio1!$KW7+Foglio1!$KZ7+Foglio1!$LC7+Foglio1!$LF7+Foglio1!$LI7+Foglio1!$LL7+Foglio1!$LO7+Foglio1!$LR7) -> 8 | LU7: =(Foglio1!$KI7+Foglio1!$KF7+Foglio1!$KL7+Foglio1!$KO7+Foglio1!$KR7+Foglio1!$KU7+Foglio1!$KX7+Foglio1!$LA7+Foglio1!$LD7+Foglio1!$LG7+Foglio1!$LJ7+Foglio1!$LM7+Foglio1!$LP7+Foglio1!$LS7) -> 15 | LV7: 43 | LW7: 31 | LX7: 11 | LY7: 21 | LZ7: 0 | MA7: 1 | MB7: 3 | MC7: 2 | MD7: =SUM(LZ7:MC7) -> 6 | ME7: 0 | MF7: 0 | MG7: 0 | MH7: 0 | MI7: =SUM(ME7:MH7) -> 0
A8: 1356c73011f9e6ce | B8: 37 | C8: M | D8: 13 | E8: 1 | F8: Yes | G8: Erotomanic | H8: 298.9 Psicosi non specificata | I8: (298.9) Psicosi NAS | L8: BBB | M8: Schizophrenia and other psychoses | N8: Aggressione nei confronti della madre | O8: 45485 | P8: 45531 | Q8: CCC | AH8: Carbamazepina RP | AI8: 1000 mg/die | AJ8: Risperidone | AK8: 8 ml/die | AL8: delorazepam | AM8: 20 gtt ore 20 | AN8: BBB | AO8: BBB | AP8: BBB | AQ8: BBB | AR8: BBB | AS8: BBB | AT8: BBB | AU8: BBB | AV8: BBB | AW8: BBB | AX8: 3 | AZ8: AAA | BA8: =(P8-O8) -> 46 | BD8: La madre vuole fargli del male | BG8: 45489 | BH8: 3 | BI8: 1 | BJ8: 3 | BK8: 2 | BL8: 2 | BM8: 3 | BN8: 2 | BO8: =SUM(Foglio1!$BH8:$BM8) -> 14 | BP8: 5 | BQ8: 3 | BR8: 0 | BS8: 49 | BT8: 3 | BU8: 2 | BV8: 2 | BW8: 1 | BX8: 1 | BY8: 3 | BZ8: 1 | CA8: 4 | CB8: 4 | CC8: 4 | CD8: 5 | CE8: 5 | CF8: 5 | CG8: 4 | CH8: 1 | CI8: 1 | CJ8: 5 | CK8: 3 | CL8: 3 | CM8: 3 | CN8: 4 | CO8: 1 | CP8: 4 | CQ8: 1 | CR8: 3 | CS8: 3 | CT8: 3 | CU8: 3 | CV8: 5 | CW8: 5 | CX8: =SUM(Foglio1!$BT8:$CW8) -> 92 | CY8: =SUM(Foglio1!$BT8+Foglio1!$BV8+Foglio1!$CP8+Foglio1!$BY8+Foglio1!$BX8+Foglio1!$CH8+Foglio1!$CS8+Foglio1!$CW8-Foglio1!$CE8) -> 17 | CZ8: =SUM(Foglio1!$CF8+Foglio1!$CA8+Foglio1!$CB8+Foglio1!$CD8+Foglio1!$CN8+Foglio1!$CC8+Foglio1!$CW8+Foglio1!$CO8+Foglio1!$CT8-Foglio1!$BU8) -> 33 | DA8: =SUM(Foglio1!$CG8+Foglio1!$CR8+Foglio1!$CQ8+Foglio1!$BU8+Foglio1!$CE8+Foglio1!$CL8+Foglio1!$CS8+Foglio1!$CT8+Foglio1!$CV8+Foglio1!$CP8) -> 33 | DB8: =SUM(Foglio1!$CU8+Foglio1!$BW8+Foglio1!$BZ8+Foglio1!$CO8+Foglio1!$BX8+Foglio1!$CC8+Foglio1!$CK8+Foglio1!$CW8) -> 19 | DC8: =SUM(Foglio1!$CI8+Foglio1!$CM8+Foglio1!$CJ8+Foglio1!$CK8+Foglio1!$BY8+Foglio1!$CH8+Foglio1!$CV8+Foglio1!$CW8) -> 26 | DD8: 0 | DE8: 0 | DF8: 0 | DG8: 0 | DH8: 0 | DI8: 0 | DJ8: 0 | DK8: 0 | DL8: 0 | DM8: 0 | DN8: 0 | DO8: 0 | DP8: 0 | DQ8: 0 | DR8: 0 | DS8: 0 | DT8: 2 | DU8: 2 | DV8: 2 | DW8: 0 | DX8: 1 | DY8: 1 | DZ8: 2 | EA8: 3 | EB8: 2 | EC8: 2 | ED8: 2 | EE8: 0 | EF8: 3 | EG8: 1 | EH8: =(Foglio1!$DE8+Foglio1!$DH8+Foglio1!$DG8+Foglio1!$DF8+Foglio1!$DM8+Foglio1!$DD8+Foglio1!$DO8+Foglio1!$DL8+Foglio1!$DN8+Foglio1!$DQ8+Foglio1!$DP8+Foglio1!$DT8+Foglio1!$DI8+Foglio1!$DK8+Foglio1!$DU8) -> 4 | EI8: =(Foglio1!$EA8+Foglio1!$EB8+Foglio1!$EE8+Foglio1!$EC8+Foglio1!$ED8+Foglio1!$DZ8+Foglio1!$DY8) -> 12 | EJ8: =(Foglio1!$DW8+Foglio1!$DV8+Foglio1!$DX8) -> 3 | EK8: =(Foglio1!$EG8+Foglio1!$EF8) -> 4 | EL8: 1 | EM8: 0 | EN8: 1 | EO8: 1 | EP8: {=SUM(EL8:EO8/4)} -> 0.75 | EQ8: 1 | ER8: 1 | ES8: 0 | ET8: 1 | EU8: in genere quando si legge qualcosa di strano sui giornali la gente è interessata a quel posto | EV8: 0 | EW8: risolvano la situazione | EX8: 1 | EY8: =(Foglio1!$EQ8+Foglio1!$ER8+Foglio1!$ES8+Foglio1!$ET8+Foglio1!$EV8+Foglio1!$EX8)/6 -> 0.66666667 | EZ8: 1 | FA8: 1 | FB8: 1 | FC8: =(Foglio1!$EZ8+Foglio1!$FA8+Foglio1!$FB8)/3 -> 1 | FD8: 1 | FE8: 1 | FF8: =(Foglio1!$FD8+Foglio1!$FE8)/2 -> 1 | FG8: ci si può trovare delle informazioni molto preziose | FH8: 1 | FI8: se una persona si trova di fronte ad una situazione che può essere redditizia, indipendentemente dalla sua inclinazione verso la legge coglie l'occasione | FJ8: 1 | FK8: è difficile accontentarsi di una sola cosa nella vita, potrebbe diventare monotona | FL8: 0 | FM8: =(Foglio1!$FH8+Foglio1!$FJ8+Foglio1!$FL8)/3 -> 0.66666667 | FN8: =(Foglio1!$EP8) -> 0.75 | FO8: =(Foglio1!$EY8+Foglio1!$FC8+Foglio1!$FF8+Foglio1!$FM8)/4 -> 0.83333333 | FP8: =(Foglio1!$EP8+Foglio1!$EY8+Foglio1!$FC8+Foglio1!$FF8+Foglio1!$FM8)/5 -> 0.81666667 | FQ8: 45525 | FR8: 1 | FS8: 1 | FT8: 1 | FU8: 1 | FV8: 2 | FW8: 1 | FX8: 2 | FY8: 4 | FZ8: 2 | GA8: 5 | GB8: 50 | GC8: 4 | GD8: 2 | GE8: 0 | GF8: 0 | GG8: 0 | GH8: 3 | GI8: 1 | GJ8: 4 | GK8: 4 | GL8: 4 | GM8: 4 | GN8: 4 | GO8: 4 | GP8: 3 | GQ8: 2 | GR8: 2 | GS8: 3 | GT8: 2 | GU8: 1 | GV8: 3 | GW8: 3 | GX8: 0 | GY8: 3 | GZ8: 0 | HA8: 2 | HB8: 1 | HC8: 1 | HD8: 1 | HE8: 3 | HF8: 3 | HG8: =SUM(GC8:HF8) -> 67 | HH8: =SUM(GC8+GE8+GY8+GH8+GG8+GQ8+HB8+HF8-GN8) -> 12 | HI8: =SUM(GO8+GJ8+GK8+GM8+GW8+GL8+HF8+GX8+HC8-GD8) -> 25 | HJ8: =SUM(GP8+HA8+GZ8+GD8+GN8+GU8+HB8+HC8+HE8+GY8) -> 20 | HK8: =SUM(HD8+GF8+GI8+GX8+GG8+GL8+GT8+HF8) -> 11 | HL8: =SUM(GR8+GV8+GS8+GT8+GH8+GQ8+HE8+HF8) -> 21 | HM8: 0 | HN8: 0 | HO8: 0 | HP8: 0 | HQ8: 0 | HR8: 0 | HS8: 0 | HT8: 1 | HU8: 0 | HV8: 0 | HW8: 0 | HX8: 0 | HY8: 0 | HZ8: 0 | IA8: 0 | IB8: 0 | IC8: 1 | ID8: 0 | IE8: 2 | IF8: 2 | IG8: 2 | IH8: 2 | II8: 1 | IJ8: 2 | IK8: 3 | IL8: 1 | IM8: 3 | IN8: 2 | IO8: 2 | IP8: 2 | IQ8: =SUM(HN8+HQ8+HP8+HO8+HV8+HM8+HX8+HU8+HW8+HZ8+HY8+IC8+HR8+HT8+ID8) -> 2 | IR8: =SUM(IJ8+IK8+IN8+IL8+IM8+II8+IH8) -> 14 | IS8: =SUM(IF8+IE8+IG8) -> 6 | IT8: =SUM(IP8+IO8) -> 4 | IU8: AAA | IV8: AAA | IW8: AAA | IX8: AAA | IY8: 1 | IZ8: 0 | JA8: 0 | JB8: 1 | JC8: =(Foglio1!$IY8+Foglio1!$IZ8+Foglio1!$JA8+Foglio1!$JB8)/4 -> 0.5 | JD8: 1 | JE8: 1 | JF8: 0 | JG8: 0 | JH8: è uno dei pochi più apprezzati dalle persone | JI8: 0 | JJ8: assumendo più dipendenti in museo si può permettere ad alcune persone di guardagnare qualcosa | JK8: 0 | JL8: =(Foglio1!$JD8+Foglio1!$JE8+Foglio1!$JF8+Foglio1!$JG8+Foglio1!$JI8+Foglio1!$JK8)/6 -> 0.33333333 | JM8: 1 | JN8: 1 | JO8: 1 | JP8: =(Foglio1!$JM8+Foglio1!$JN8+Foglio1!$JO8)/3 -> 1 | JQ8: 1 | JR8: 1 | JS8: =(Foglio1!$JQ8+Foglio1!$JR8)/2 -> 1 | JT8: sono sempre in cerca di un articolo e per questo possono diventare fastidiosi con le persone | JU8: 1 | JV8: a volte qualcuno può fare di tutto per sembrare minaccioso ma così facendo in realtà dimostra solo qualche debolezza | JW8: 0 | JX8: ogni cosa ha un lato positivo e negativo | JY8: 1 | JZ8: =(Foglio1!$JU8+Foglio1!$JW8+Foglio1!$JY8)/3 -> 0.66666667 | KA8: =(Foglio1!$JC8) -> 0.5 | KB8: =(Foglio1!$JL8+Foglio1!$JP8+Foglio1!$JS8+Foglio1!$JZ8)/4 -> 0.75 | KC8: =(Foglio1!$JC8+Foglio1!$JL8+Foglio1!$JP8+Foglio1!$JS8+Foglio1!$JZ8)/5 -> 0.7 | KD8: arrivano sempre in ritardo | KE8: 0 | KF8: 2 | KG8: all'apparenza possono far pensare ad un certo tipo di persona ma poi in sostanza non sono un granché | KH8: 0 | KI8: 2 | KJ8: pensano solo a come vestirsi, all'apprenza | KK8: 0 | KL8: 2 | KM8: probabilmente il matrimonio durerà poco | KN8: 0 | KO8: 0 | KP8: ci si può fare molto affidamento | KQ8: 2 | KR8: 3 | KS8: sono lenti | KT8: 2 | KU8: 1 | KV8: conosce le tecniche orientali | KW8: 0 | KX8: 2 | KY8: le loro frasi, il loro lavoro resta poco nella vita delle persone | KZ8: 0 | LA8: 0 | LB8: sono stonati | LC8: 0 | LD8: 1 | LE8: sono persone su cui fare molto affidamento grazie alle loro esperienze | LF8: 2 | LG8: 3 | LH8: passano la maggior parte del tempo a prendere il sole | LI8: 2 | LJ8: 1 | LK8: gli piace solo vantarsi ma in sostanza non danno niente | LL8: 2 | LM8: 2 | LN8: sono teneri | LO8: 2 | LP8: 2 | LQ8: usano tecniche non molto moderne | LR8: 0 | LS8: 0 | LT8: =(Foglio1!$KE8+Foglio1!$KH8+Foglio1!$KK8+Foglio1!$KN8+Foglio1!$KQ8+Foglio1!$KT8+Foglio1!$KW8+Foglio1!$KZ8+Foglio1!$LC8+Foglio1!$LF8+Foglio1!$LI8+Foglio1!$LL8+Foglio1!$LO8+Foglio1!$LR8) -> 12 | LU8: =(Foglio1!$KI8+Foglio1!$KF8+Foglio1!$KL8+Foglio1!$KO8+Foglio1!$KR8+Foglio1!$KU8+Foglio1!$KX8+Foglio1!$LA8+Foglio1!$LD8+Foglio1!$LG8+Foglio1!$LJ8+Foglio1!$LM8+Foglio1!$LP8+Foglio1!$LS8) -> 21 | LV8: 53 | LW8: 46 | LX8: 22 | LY8: 33 | LZ8: 0 | MA8: 0 | MB8: 1 | MC8: 4 | MD8: =SUM(LZ8:MC8) -> 5 | ME8: 0 | MF8: 0 | MG8: 0 | MH8: 0 | MI8: =SUM(ME8:MH8) -> 0
